Workbook
Name QBCANSUPPORTUPDATE: TRUE
Name QBCANSUPPORTUPDATE: TRUE
Name QBCOMPANYFILENAME: "C:\ElCentroWorkingArchive\libertad.qbw"
Name QBCOMPANYFILENAME: "C:\ElCentroWorkingArchive\libertad.qbw"
Name QBENDDATE: 20220630
Name QBENDDATE: 20220630
Name QBHEADERSONSCREEN: FALSE
Name QBHEADERSONSCREEN: FALSE
Name QBMETADATASIZE: 5924
Name QBMETADATASIZE: 5924
Name QBPRESERVECOLOR: TRUE
Name QBPRESERVECOLOR: TRUE
Name QBPRESERVEFONT: TRUE
Name QBPRESERVEFONT: TRUE
Name QBPRESERVEROWHEIGHT: TRUE
Name QBPRESERVEROWHEIGHT: TRUE
Name QBPRESERVESPACE: FALSE
Name QBPRESERVESPACE: FALSE
Name QBREPORTCOLAXIS: 8
Name QBREPORTCOLAXIS: 0
Name QBREPORTCOMPANYID: "865a3afdace341f0871aaf9656bcdc8e"
Name QBREPORTCOMPANYID: "865a3afdace341f0871aaf9656bcdc8e"
Name QBREPORTCOMPARECOL_ANNUALBUDGET: FALSE
Name QBREPORTCOMPARECOL_ANNUALBUDGET: FALSE
Name QBREPORTCOMPARECOL_AVGCOGS: FALSE
Name QBREPORTCOMPARECOL_AVGCOGS: FALSE
Name QBREPORTCOMPARECOL_AVGPRICE: FALSE
Name QBREPORTCOMPARECOL_AVGPRICE: FALSE
Name QBREPORTCOMPARECOL_BUDDIFF: FALSE
Name QBREPORTCOMPARECOL_BUDDIFF: FALSE
Name QBREPORTCOMPARECOL_BUDGET: FALSE
Name QBREPORTCOMPARECOL_BUDGET: FALSE
Name QBREPORTCOMPARECOL_BUDPCT: FALSE
Name QBREPORTCOMPARECOL_BUDPCT: FALSE
Name QBREPORTCOMPARECOL_COGS: FALSE
Name QBREPORTCOMPARECOL_COGS: FALSE
Name QBREPORTCOMPARECOL_EXCLUDEAMOUNT: FALSE
Name QBREPORTCOMPARECOL_EXCLUDEAMOUNT: FALSE
Name QBREPORTCOMPARECOL_EXCLUDECURPERIOD: FALSE
Name QBREPORTCOMPARECOL_EXCLUDECURPERIOD: FALSE
Name QBREPORTCOMPARECOL_FORECAST: FALSE
Name QBREPORTCOMPARECOL_FORECAST: FALSE
Name QBREPORTCOMPARECOL_GROSSMARGIN: FALSE
Name QBREPORTCOMPARECOL_GROSSMARGIN: FALSE
Name QBREPORTCOMPARECOL_GROSSMARGINPCT: FALSE
Name QBREPORTCOMPARECOL_GROSSMARGINPCT: FALSE
Name QBREPORTCOMPARECOL_HOURS: FALSE
Name QBREPORTCOMPARECOL_HOURS: FALSE
Name QBREPORTCOMPARECOL_PCTCOL: FALSE
Name QBREPORTCOMPARECOL_PCTCOL: FALSE
Name QBREPORTCOMPARECOL_PCTEXPENSE: FALSE
Name QBREPORTCOMPARECOL_PCTEXPENSE: FALSE
Name QBREPORTCOMPARECOL_PCTINCOME: FALSE
Name QBREPORTCOMPARECOL_PCTINCOME: FALSE
Name QBREPORTCOMPARECOL_PCTOFSALES: FALSE
Name QBREPORTCOMPARECOL_PCTOFSALES: FALSE
Name QBREPORTCOMPARECOL_PCTROW: FALSE
Name QBREPORTCOMPARECOL_PCTROW: FALSE
Name QBREPORTCOMPARECOL_PPDIFF: FALSE
Name QBREPORTCOMPARECOL_PPDIFF: FALSE

Sheet Review-Checkpoints
B2: Checklist for Review Exempt Org Tax Return
B4: Revenue - Checks
B5: S No | C5: Check Points | D5: Verification Check | E5: Review Points | F5: Compliance Check
B6: 1 | C6: Is there any Govt Grant | D6: =IF('Part VIII - Revenue'!D8>0,"Yes","No") -> No | E6: Is Contributed list updated in Schedule B and RRF-1
B7: 2 | C7: Is there any other contribution | D7: =IF('Part VIII - Revenue'!D9>0,"Yes","No") -> No | E7: Is Contributed list updated in Schedule B
B8: 3 | C8: Is there any Non cash contribution more than $25000 | D8: =IF('Part VIII - Revenue'!D10>25000,"Yes","No") -> No | E8: Are details updated in Schedule M
B9: 4 | C9: Is there any donated services / In-Kind service | D9: =IF(ISNUMBER(MATCH("Adj-DS",SOR!F:F, 0)), "Yes", "No") -> No | E9: Is it part of reconciliation on page -12 and schedule D
B10: 5 | C10: Is there any Unrealized Gain / Loss | D10: =IF(ISNUMBER(MATCH("Adj-UG",SOR!F:F, 0)), "Yes", "No") -> No | E10: Is it part of reconciliation on page -12 and schedule D
B11: 6 | C11: Is there any Program Service Revenue | D11: =IF('Part VIII - Revenue'!E19>0,"Yes","No") -> No | E11: Is it reconciled with Page 2
B12: 7 | C12: Is there any Investment Income | D12: =IF('Part VIII - Revenue'!E20>0,"Yes","No") -> No | E12: It should be Gross income without effect of Unrealized gain and Investment Exp
B13: 8 | C13: Is there any Investment Management Exp | D13: =IF('Part IX - Expenses'!C19>0,"Yes","No") -> No | E13: Is it showing in Line 11f of part IX
B14: 9 | C14: Is there Fundraising Income More Than $15000 | D14: =+IF(('Part VIII - Revenue'!D6+'Part VIII - Revenue'!D33)>15000,"Yes","No") -> No | E14: Is Schedule G Filled properly
B17: Expenses - Checks
B18: S No | C18: Check Points | D18: Verification Check | E18: Review Points | F18: Compliance Check
B19: 1 | C19: Is there any Grants and Other Assistance paid more than $5000 | D19: =IF(OR('Part IX - Expenses'!C4>5000, 'Part IX - Expenses'!C5>5000), "Yes", "No") -> No | E19: Is Schedule I Filled Properly
B20: 2 | C20: Is there Professional Fundraising Services More Than $15000 | D20: =+IF('Part IX - Expenses'!C18>15000,"Yes","No") -> No | E20: Is Schedule G Filled properly
B21: 3 | C21: Is there any Depreciation expenses | D21: =+IF('Part IX - Expenses'!C31>0,"Yes","No") -> No | E21: Is Form 3885 or 3885F Filled properly
B22: 4 | C22: Is Total of Program Service Expenses Reconciled with page 2
B25: Balance Sheet - Checks
B26: S No | C26: Check Points | D26: Verification Check | E26: Review Points | F26: Compliance Check
B27: 1 | C27: Is there any receivable from or payable to disqualified person | D27: =+IF(('Part X - Balance Sheet'!E8+'Part X - Balance Sheet'!E27)>0,"Yes","No") -> No | E27: Is Schedule L filled properly and Line 1 of RRF-1 marked yes
B28: 2 | C28: Is there any other transaction with disqualified person | D28: No | E28: Is Schedule L filled properly and Line 1 of RRF-1 marked yes
B29: 3 | C29: Is there any Escrow and Custodial Arrangements | D29: =+IF('Part X - Balance Sheet'!E26>0,"Yes","No") -> No | E29: Is Part IV of Schedule D filled properly
B30: 4 | C30: Is there any fixed assets | D30: =IF('Part X - Balance Sheet'!E15>0,"Yes","No") -> No | E30: Is Part VI of schedule D matched with Audit Report
B31: 5 | C31: Is organization hold assets in donor-restricted endowments | D31: No | E31: Is Part V of Schedule D filled properly
B32: 6 | C32: Is there any related party (See Note in Audit Report) | D32: No | E32: Is Schedule R filled properly
B35: Other - Checks
B36: S No | C36: Check Points | D36: Verification Check | E36: Review Points | F36: Compliance Check
B37: 1 | C37: Is all revenue figures updated in schedule A | D37: No
B38: 2 | C38: Is Form-199 figures matched with Audit Report or Books | D38: Yes
B39: 3 | C39: Are figures updated in Form RRF-1 | D39: No
B40: 4 | C40: Is it being submitted per Final Audit Report figures | D40: No | E40: Are these lines marked "✔" (Part IV Line 12a/b, Part XII Line 2a,b,c, RRF-1 Line 8)
B41: 5 | C41: Is there any footnote regarding the uncertain income tax position in the Final Audit Report | D41: No | E41: Is it stated in Schedule D Supplemental Information
B42: 6 | C42: Is single audit applicable in Audit Report (SEFA) | D42: No | E42: Are these lines marked "✔" (Part XII Line 3a and 3b)
B43: 7 | C43: Is the FY ending other than December | D43: No | E43: Is CA copy made and compensation statement generated in form 199.

Sheet Part VIII - Revenue
A2: Part VIII - Statement of Revenue
A3: Line | B3: Particulars | E3: Total Revenue | F3: Related or Exempt Function Income | G3: Unrelated Business Revenue | H3: Revenue excluded from tax under $512, 513 or 514 | I3: Last Year
A4: 1a | B4: Federated Campaigns | D4: =+SUMIF(SOR!$F:$F,'Part VIII - Revenue'!$A4,SOR!$B:$B) -> 0 | I4: =+SUMIF(SOR!$H:$H,'Part VIII - Revenue'!$A4,SOR!$G:$G) -> 0
A5: 1b | B5: Membership Dues | D5: =+SUMIF(SOR!$F:$F,'Part VIII - Revenue'!$A5,SOR!$B:$B) -> 0 | I5: =+SUMIF(SOR!$H:$H,'Part VIII - Revenue'!$A5,SOR!$G:$G) -> 0
A6: 1c | B6: Fundraising Events | D6: =+SUMIF(SOR!$F:$F,'Part VIII - Revenue'!$A6,SOR!$B:$B) -> 0 | I6: =+SUMIF(SOR!$H:$H,'Part VIII - Revenue'!$A6,SOR!$G:$G) -> 0
A7: 1d | B7: Related Organisations | D7: =+SUMIF(SOR!$F:$F,'Part VIII - Revenue'!$A7,SOR!$B:$B) -> 0 | I7: =+SUMIF(SOR!$H:$H,'Part VIII - Revenue'!$A7,SOR!$G:$G) -> 0
A8: 1e | B8: Government Grants/ Contributions | D8: =+SUMIF(SOR!$F:$F,'Part VIII - Revenue'!$A8,SOR!$B:$B) -> 0 | I8: =+SUMIF(SOR!$H:$H,'Part VIII - Revenue'!$A8,SOR!$G:$G) -> 0
A9: 1f | B9: All Other contributions, gifts, grants and similar amounts not listed above | D9: =+SUMIF(SOR!$F:$F,'Part VIII - Revenue'!$A9,SOR!$B:$B)+SUMIF(SOR!$F:$F,'Part VIII - Revenue'!$A10,SOR!$B:$B) -> 0 | I9: =+SUMIF(SOR!$H:$H,'Part VIII - Revenue'!$A9,SOR!$G:$G) -> 0
A10: 1g | B10: Noncash Contributions included in lines 1a-1f | D10: =+SUMIF(SOR!$F:$F,'Part VIII - Revenue'!$A10,SOR!$B:$B) -> 0 | I10: =+SUMIF(SOR!$H:$H,'Part VIII - Revenue'!$A10,SOR!$G:$G) -> 0
A11: 1h | B11: Total. Add Lines 1a-1f | E11: =+SUM(D4:D9) -> 0 | I11: =SUM(I4:I10) -> 0
A12: 2 | B12: Program Service Revenue | D12: Business Code
A13: 2a | B13: =IFERROR(+INDEX(SOR!A:F,MATCH('Part VIII - Revenue'!A13,SOR!F:F,0),1),"") | E13: =SUM(F13:H13) -> 0 | F13: =+SUMIF(SOR!$F:$F,'Part VIII - Revenue'!$A:$A,SOR!C:C) -> 0 | G13: =+SUMIF(SOR!$F:$F,'Part VIII - Revenue'!$A:$A,SOR!D:D) -> 0 | H13: =+SUMIF(SOR!$F:$F,'Part VIII - Revenue'!$A:$A,SOR!E:E) -> 0 | I13: =+SUMIF(SOR!$H:$H,'Part VIII - Revenue'!$A13,SOR!$G:$G) -> 0
A14: 2b | B14: =IFERROR(+INDEX(SOR!A:F,MATCH('Part VIII - Revenue'!A14,SOR!F:F,0),1),"") | E14: =SUM(F14:H14) -> 0 | F14: =+SUMIF(SOR!$F:$F,'Part VIII - Revenue'!$A:$A,SOR!C:C) -> 0 | G14: =+SUMIF(SOR!$F:$F,'Part VIII - Revenue'!$A:$A,SOR!D:D) -> 0 | H14: =+SUMIF(SOR!$F:$F,'Part VIII - Revenue'!$A:$A,SOR!E:E) -> 0 | I14: =+SUMIF(SOR!$H:$H,'Part VIII - Revenue'!$A14,SOR!$G:$G) -> 0
A15: 2c | B15: =IFERROR(+INDEX(SOR!A:F,MATCH('Part VIII - Revenue'!A15,SOR!F:F,0),1),"") | E15: =SUM(F15:H15) -> 0 | F15: =+SUMIF(SOR!$F:$F,'Part VIII - Revenue'!$A:$A,SOR!C:C) -> 0 | G15: =+SUMIF(SOR!$F:$F,'Part VIII - Revenue'!$A:$A,SOR!D:D) -> 0 | H15: =+SUMIF(SOR!$F:$F,'Part VIII - Revenue'!$A:$A,SOR!E:E) -> 0 | I15: =+SUMIF(SOR!$H:$H,'Part VIII - Revenue'!$A15,SOR!$G:$G) -> 0
A16: 2d | B16: =IFERROR(+INDEX(SOR!A:F,MATCH('Part VIII - Revenue'!A16,SOR!F:F,0),1),"") | E16: =SUM(F16:H16) -> 0 | F16: =+SUMIF(SOR!$F:$F,'Part VIII - Revenue'!$A:$A,SOR!C:C) -> 0 | G16: =+SUMIF(SOR!$F:$F,'Part VIII - Revenue'!$A:$A,SOR!D:D) -> 0 | H16: =+SUMIF(SOR!$F:$F,'Part VIII - Revenue'!$A:$A,SOR!E:E) -> 0 | I16: =+SUMIF(SOR!$H:$H,'Part VIII - Revenue'!$A16,SOR!$G:$G) -> 0
A17: 2e | B17: =IFERROR(+INDEX(SOR!A:F,MATCH('Part VIII - Revenue'!A17,SOR!F:F,0),1),"") | E17: =SUM(F17:H17) -> 0 | F17: =+SUMIF(SOR!$F:$F,'Part VIII - Revenue'!$A:$A,SOR!C:C) -> 0 | G17: =+SUMIF(SOR!$F:$F,'Part VIII - Revenue'!$A:$A,SOR!D:D) -> 0 | H17: =+SUMIF(SOR!$F:$F,'Part VIII - Revenue'!$A:$A,SOR!E:E) -> 0 | I17: =+SUMIF(SOR!$H:$H,'Part VIII - Revenue'!$A17,SOR!$G:$G) -> 0
A18: 2f | B18: All other program service revenue | E18: =SUM(F18:H18) -> 0 | F18: =+SUMIF(SOR!$F:$F,'Part VIII - Revenue'!$A:$A,SOR!C:C) -> 0 | G18: =+SUMIF(SOR!$F:$F,'Part VIII - Revenue'!$A:$A,SOR!D:D) -> 0 | H18: =+SUMIF(SOR!$F:$F,'Part VIII - Revenue'!$A:$A,SOR!E:E) -> 0 | I18: =+SUMIF(SOR!$H:$H,'Part VIII - Revenue'!$A18,SOR!$G:$G) -> 0
A19: 2g | B19: Total. Add Lines 2a-2f | E19: =+SUM(E13:E18) -> 0 | I19: =SUM(I13:I18) -> 0
A20: 3 | B20: Investment Income (dividends, interest and other similar amounts) | E20: =+SUM(F20:H20) -> 0 | F20: =+SUMIF(SOR!$F:$F,'Part VIII - Revenue'!$A:$A,SOR!C:C) -> 0 | G20: =+SUMIF(SOR!$F:$F,'Part VIII - Revenue'!$A:$A,SOR!D:D) -> 0 | H20: =+SUMIF(SOR!$F:$F,'Part VIII - Revenue'!$A:$A,SOR!E:E) -> 0 | I20: =+SUMIF(SOR!$H:$H,'Part VIII - Revenue'!$A20,SOR!$G:$G) -> 0
A21: 4 | B21: Income from Investment of tax-exempt bond proceeds | E21: =SUM(F21:H21) -> 0 | F21: =+SUMIF(SOR!$F:$F,'Part VIII - Revenue'!$A:$A,SOR!C:C) -> 0 | G21: =+SUMIF(SOR!$F:$F,'Part VIII - Revenue'!$A:$A,SOR!D:D) -> 0 | H21: =+SUMIF(SOR!$F:$F,'Part VIII - Revenue'!$A:$A,SOR!E:E) -> 0 | I21: =+SUMIF(SOR!$H:$H,'Part VIII - Revenue'!$A21,SOR!$G:$G) -> 0
A22: 5 | B22: Royalties | E22: =SUM(F22:H22) -> 0 | F22: =+SUMIF(SOR!$F:$F,'Part VIII - Revenue'!$A:$A,SOR!C:C) -> 0 | G22: =+SUMIF(SOR!$F:$F,'Part VIII - Revenue'!$A:$A,SOR!D:D) -> 0 | H22: =+SUMIF(SOR!$F:$F,'Part VIII - Revenue'!$A:$A,SOR!E:E) -> 0 | I22: =+SUMIF(SOR!$H:$H,'Part VIII - Revenue'!$A22,SOR!$G:$G) -> 0
C23: Real | D23: Personal
A24: 6a | B24: Gross Rents | C24: =+SUMIF(SOR!F:F,"6a-R",SOR!B:B) -> 0 | D24: =+SUMIF(SOR!F:F,"6a-P",SOR!B:B) -> 0 | I24: =+SUMIF(SOR!H:H,"6a-R",SOR!G:G)+SUMIF(SOR!H:H,"6a-P",SOR!G:G) -> 0
A25: 6b | B25: Less: Rental Expenses | C25: =+SUMIF(SOR!F:F,"6b-R",SOR!B:B) -> 0 | D25: =+SUMIF(SOR!F:F,"6b-P",SOR!B:B) -> 0 | I25: =+SUMIF(SOR!H:H,"6b-R",SOR!G:G)+SUMIF(SOR!H:H,"6b-P",SOR!G:G) -> 0
A26: 6c | B26: Rental Income or (Loss) | C26: =+C24-C25 -> 0 | D26: =D24-D25 -> 0 | I26: =+I24-I25 -> 0
A27: 6d | B27: Net Rental Income or (Loss) | E27: =+SUM(F27:H27) -> 0 | F27: =+SUMIF(SOR!F:F,"6a-R",SOR!C:C)-SUMIF(SOR!F:F,"6b-R",SOR!C:C)+SUMIF(SOR!F:F,"6a-P",SOR!C:C)-SUMIF(SOR!F:F,"6b-P",SOR!C:C) -> 0 | G27: =+SUMIF(SOR!F:F,"6a-R",SOR!D:D)-SUMIF(SOR!F:F,"6b-R",SOR!D:D)+SUMIF(SOR!F:F,"6a-P",SOR!D:D)-SUMIF(SOR!F:F,"6b-P",SOR!D:D) -> 0 | H27: =+SUMIF(SOR!F:F,"6a-R",SOR!E:E)-SUMIF(SOR!F:F,"6b-R",SOR!E:E)+SUMIF(SOR!F:F,"6a-P",SOR!E:E)-SUMIF(SOR!F:F,"6b-P",SOR!E:E) -> 0 | I27: =+I26 -> 0
C28: Securities | D28: Other
A29: 7a | B29: Gross Amounts from Sales of Assets other than Inventory | C29: =+SUMIF(SOR!F:F,"7a-S",SOR!B:B) -> 0 | D29: =+SUMIF(SOR!F:F,"7a-O",SOR!B:B) -> 0 | I29: =+SUMIF(SOR!H:H,"7a-S",SOR!G:G)+SUMIF(SOR!H:H,"7a-O",SOR!G:G) -> 0
A30: 7b | B30: Less: Cost or Other Basis and sales expenses | C30: =+SUMIF(SOR!F:F,"7b-S",SOR!B:B) -> 0 | D30: =+SUMIF(SOR!F:F,"7b-o",SOR!B:B) -> 0 | I30: =+SUMIF(SOR!H:H,"7b-S",SOR!G:G)+SUMIF(SOR!H:H,"7b-O",SOR!G:G) -> 0
A31: 7c | B31: Gain or (Loss) | C31: =+C29-C30 -> 0 | D31: =+D29-D30 -> 0 | I31: =+I29-I30 -> 0
A32: 7d | B32: Net Gain or (Loss) | E32: =SUM(F32:H32) -> 0 | F32: =+SUMIF(SOR!F:F,"7a-S",SOR!C:C)-SUMIF(SOR!F:F,"7b-S",SOR!C:C)+SUMIF(SOR!F:F,"7a-O",SOR!C:C)-SUMIF(SOR!F:F,"7b-O",SOR!C:C) -> 0 | G32: =+SUMIF(SOR!F:F,"7a-S",SOR!D:D)-SUMIF(SOR!F:F,"7b-S",SOR!D:D)+SUMIF(SOR!F:F,"7a-O",SOR!D:D)-SUMIF(SOR!F:F,"7b-O",SOR!D:D) -> 0 | H32: =+SUMIF(SOR!F:F,"7a-S",SOR!E:E)-SUMIF(SOR!F:F,"7b-S",SOR!E:E)+SUMIF(SOR!F:F,"7a-O",SOR!E:E)-SUMIF(SOR!F:F,"7b-O",SOR!E:E) -> 0 | I32: =+I31 -> 0
A33: 8a | B33: Gross Income from fundraising activities (not including contributions on line 1c) | D33: =+SUMIF(SOR!F:F,A33,SOR!B:B) -> 0 | I33: =+SUMIF(SOR!$H:$H,'Part VIII - Revenue'!$A33,SOR!$G:$G) -> 0
A34: 8b | B34: Less: Direct Expenses | D34: =+SUMIF(SOR!F:F,A34,SOR!B:B) -> 0 | I34: =+SUMIF(SOR!$H:$H,'Part VIII - Revenue'!$A34,SOR!$G:$G) -> 0
A35: 8c | B35: Net Income or (loss) from fund raising activities | E35: =+D33-D34 -> 0 | I35: =+I33-I34 -> 0
A36: 9a | B36: Gross Income from Gaming Activities | D36: =+SUMIF(SOR!F:F,A36,SOR!B:B) -> 0 | I36: =+SUMIF(SOR!$H:$H,'Part VIII - Revenue'!$A36,SOR!$G:$G) -> 0
A37: 9b | B37: Less: Direct Expenses | D37: =+SUMIF(SOR!F:F,A37,SOR!B:B) -> 0 | I37: =+SUMIF(SOR!$H:$H,'Part VIII - Revenue'!$A37,SOR!$G:$G) -> 0
A38: 9c | B38: Net Income or (loss) from gaming activities | E38: =SUM(F38:H38) -> 0 | F38: =+SUMIF(SOR!F:F,"9a",SOR!C:C)-SUMIF(SOR!F:F,"9b",SOR!C:C) -> 0 | G38: =+SUMIF(SOR!F:F,"9a",SOR!D:D)-SUMIF(SOR!F:F,"9b",SOR!D:D) -> 0 | H38: =+SUMIF(SOR!F:F,"9a",SOR!E:E)-SUMIF(SOR!F:F,"9b",SOR!E:E) -> 0 | I38: =+I36-I37 -> 0
A39: 10a | B39: Gross Sales of Inventory, less returns and allowances | D39: =+SUMIF(SOR!F:F,A39,SOR!B:B) -> 0 | I39: =+SUMIF(SOR!$H:$H,'Part VIII - Revenue'!$A39,SOR!$G:$G) -> 0
A40: 10b | B40: Less: COGS | D40: =+SUMIF(SOR!F:F,A40,SOR!B:B) -> 0 | I40: =+SUMIF(SOR!$H:$H,'Part VIII - Revenue'!$A40,SOR!$G:$G) -> 0
A41: 10c | B41: Net Income or (loss) from Sales of Inventory | E41: =SUM(F41:H41) -> 0 | F41: =+SUMIF(SOR!F:F,"10a",SOR!C:C)-SUMIF(SOR!F:F,"10b",SOR!C:C) -> 0 | G41: =+SUMIF(SOR!F:F,"10a",SOR!D:D)-SUMIF(SOR!F:F,"10b",SOR!D:D) -> 0 | H41: =+SUMIF(SOR!F:F,"10a",SOR!E:E)-SUMIF(SOR!F:F,"10b",SOR!E:E) -> 0 | I41: =+I39-I40 -> 0
...

Sheet Part IX - Expenses
A2: Part IX: Statement of Functional Expenses
A3: Line | B3: Particulars | C3: Total | D3: Program Service | E3: Management | F3: Fundraising | G3: Last Year
A4: 1 | B4: Grants and other assistance to domestic governments and domestic organisations | C4: =SUM(D4:F4) -> 0 | D4: =+SUMIF(SOFE!$J:$J,'Part IX - Expenses'!$A4,SOFE!E:E) -> 0 | G4: =+SUMIF(SOFE!K:K,'Part IX - Expenses'!A4,SOFE!I:I) -> 0
A5: 2 | B5: Grants and other assistance to domestic individuals | C5: =SUM(D5:F5) -> 0 | D5: =+SUMIF(SOFE!$J:$J,'Part IX - Expenses'!$A5,SOFE!E:E) -> 0 | G5: =+SUMIF(SOFE!K:K,'Part IX - Expenses'!A5,SOFE!I:I) -> 0
A6: 3 | B6: Grants and other assistance foreign organizations, foreign governments and foreign individuals | C6: =SUM(D6:F6) -> 0 | D6: =+SUMIF(SOFE!$J:$J,'Part IX - Expenses'!$A6,SOFE!E:E) -> 0 | G6: =+SUMIF(SOFE!K:K,'Part IX - Expenses'!A6,SOFE!I:I) -> 0
A7: 4 | B7: Benefits paid to or for members | C7: =SUM(D7:F7) -> 0 | D7: =+SUMIF(SOFE!$J:$J,'Part IX - Expenses'!$A7,SOFE!E:E) -> 0 | G7: =+SUMIF(SOFE!K:K,'Part IX - Expenses'!A7,SOFE!I:I) -> 0
A8: 5 | B8: Compensation of Current officers, directors, trustees and key employees | C8: =SUM(D8:F8) -> 0 | D8: =+SUMIF(SOFE!$J:$J,'Part IX - Expenses'!$A8,SOFE!E:E) -> 0 | E8: =+SUMIF(SOFE!$J:$J,'Part IX - Expenses'!$A8,SOFE!F:F) -> 0 | F8: =+SUMIF(SOFE!$J:$J,'Part IX - Expenses'!$A8,SOFE!G:G) -> 0 | G8: =+SUMIF(SOFE!K:K,'Part IX - Expenses'!A8,SOFE!I:I) -> 0
A9: 6 | B9: Compensations not included above to disqualified persons | C9: =SUM(D9:F9) -> 0 | D9: =+SUMIF(SOFE!$J:$J,'Part IX - Expenses'!$A9,SOFE!E:E) -> 0 | E9: =+SUMIF(SOFE!$J:$J,'Part IX - Expenses'!$A9,SOFE!F:F) -> 0 | F9: =+SUMIF(SOFE!$J:$J,'Part IX - Expenses'!$A9,SOFE!G:G) -> 0 | G9: =+SUMIF(SOFE!K:K,'Part IX - Expenses'!A9,SOFE!I:I) -> 0
A10: 7 | B10: Other Salaries and wages | C10: =SUM(D10:F10) -> 0 | D10: =+SUMIF(SOFE!$J:$J,'Part IX - Expenses'!$A10,SOFE!E:E) -> 0 | E10: =+SUMIF(SOFE!$J:$J,'Part IX - Expenses'!$A10,SOFE!F:F) -> 0 | F10: =+SUMIF(SOFE!$J:$J,'Part IX - Expenses'!$A10,SOFE!G:G) -> 0 | G10: =+SUMIF(SOFE!K:K,'Part IX - Expenses'!A10,SOFE!I:I) -> 0
A11: 8 | B11: Pension plam accruals & contributions (incl. 401(k) and 403(b) employer contr.) | C11: =SUM(D11:F11) -> 0 | D11: =+SUMIF(SOFE!$J:$J,'Part IX - Expenses'!$A11,SOFE!E:E) -> 0 | E11: =+SUMIF(SOFE!$J:$J,'Part IX - Expenses'!$A11,SOFE!F:F) -> 0 | F11: =+SUMIF(SOFE!$J:$J,'Part IX - Expenses'!$A11,SOFE!G:G) -> 0 | G11: =+SUMIF(SOFE!K:K,'Part IX - Expenses'!A11,SOFE!I:I) -> 0
A12: 9 | B12: Other Employee Benefits | C12: =SUM(D12:F12) -> 0 | D12: =+SUMIF(SOFE!$J:$J,'Part IX - Expenses'!$A12,SOFE!E:E) -> 0 | E12: =+SUMIF(SOFE!$J:$J,'Part IX - Expenses'!$A12,SOFE!F:F) -> 0 | F12: =+SUMIF(SOFE!$J:$J,'Part IX - Expenses'!$A12,SOFE!G:G) -> 0 | G12: =+SUMIF(SOFE!K:K,'Part IX - Expenses'!A12,SOFE!I:I) -> 0
A13: 10 | B13: Payroll taxes | C13: =SUM(D13:F13) -> 0 | D13: =+SUMIF(SOFE!$J:$J,'Part IX - Expenses'!$A13,SOFE!E:E) -> 0 | E13: =+SUMIF(SOFE!$J:$J,'Part IX - Expenses'!$A13,SOFE!F:F) -> 0 | F13: =+SUMIF(SOFE!$J:$J,'Part IX - Expenses'!$A13,SOFE!G:G) -> 0 | G13: =+SUMIF(SOFE!K:K,'Part IX - Expenses'!A13,SOFE!I:I) -> 0
A14: 11a | B14: Management | C14: =SUM(D14:F14) -> 0 | D14: =+SUMIF(SOFE!$J:$J,'Part IX - Expenses'!$A14,SOFE!E:E) -> 0 | E14: =+SUMIF(SOFE!$J:$J,'Part IX - Expenses'!$A14,SOFE!F:F) -> 0 | F14: =+SUMIF(SOFE!$J:$J,'Part IX - Expenses'!$A14,SOFE!G:G) -> 0 | G14: =+SUMIF(SOFE!K:K,'Part IX - Expenses'!A14,SOFE!I:I) -> 0
A15: 11b | B15: Legal | C15: =SUM(D15:F15) -> 0 | D15: =+SUMIF(SOFE!$J:$J,'Part IX - Expenses'!$A15,SOFE!E:E) -> 0 | E15: =+SUMIF(SOFE!$J:$J,'Part IX - Expenses'!$A15,SOFE!F:F) -> 0 | F15: =+SUMIF(SOFE!$J:$J,'Part IX - Expenses'!$A15,SOFE!G:G) -> 0 | G15: =+SUMIF(SOFE!K:K,'Part IX - Expenses'!A15,SOFE!I:I) -> 0
A16: 11c | B16: Accounting | C16: =SUM(D16:F16) -> 0 | D16: =+SUMIF(SOFE!$J:$J,'Part IX - Expenses'!$A16,SOFE!E:E) -> 0 | E16: =+SUMIF(SOFE!$J:$J,'Part IX - Expenses'!$A16,SOFE!F:F) -> 0 | F16: =+SUMIF(SOFE!$J:$J,'Part IX - Expenses'!$A16,SOFE!G:G) -> 0 | G16: =+SUMIF(SOFE!K:K,'Part IX - Expenses'!A16,SOFE!I:I) -> 0
A17: 11d | B17: Lobbying | C17: =SUM(D17:F17) -> 0 | D17: =+SUMIF(SOFE!$J:$J,'Part IX - Expenses'!$A17,SOFE!E:E) -> 0 | E17: =+SUMIF(SOFE!$J:$J,'Part IX - Expenses'!$A17,SOFE!F:F) -> 0 | F17: =+SUMIF(SOFE!$J:$J,'Part IX - Expenses'!$A17,SOFE!G:G) -> 0 | G17: =+SUMIF(SOFE!K:K,'Part IX - Expenses'!A17,SOFE!I:I) -> 0
A18: 11e | B18: Professional Fundraising services | C18: =SUM(D18:F18) -> 0 | F18: =+SUMIF(SOFE!$J:$J,'Part IX - Expenses'!$A18,SOFE!G:G) -> 0 | G18: =+SUMIF(SOFE!K:K,'Part IX - Expenses'!A18,SOFE!I:I) -> 0
A19: 11f | B19: Investment Management Fees | C19: =SUM(D19:F19) -> 0 | D19: =+SUMIF(SOFE!$J:$J,'Part IX - Expenses'!$A19,SOFE!E:E) -> 0 | E19: =+SUMIF(SOFE!$J:$J,'Part IX - Expenses'!$A19,SOFE!F:F) -> 0 | F19: =+SUMIF(SOFE!$J:$J,'Part IX - Expenses'!$A19,SOFE!G:G) -> 0 | G19: =+SUMIF(SOFE!K:K,'Part IX - Expenses'!A19,SOFE!I:I) -> 0
A20: 11g | B20: Other Fees for service | C20: =SUM(D20:F20) -> 0 | D20: =+SUMIF(SOFE!$J:$J,'Part IX - Expenses'!$A20,SOFE!E:E) -> 0 | E20: =+SUMIF(SOFE!$J:$J,'Part IX - Expenses'!$A20,SOFE!F:F) -> 0 | F20: =+SUMIF(SOFE!$J:$J,'Part IX - Expenses'!$A20,SOFE!G:G) -> 0 | G20: =+SUMIF(SOFE!K:K,'Part IX - Expenses'!A20,SOFE!I:I) -> 0
A21: 12 | B21: Advertising and promotion | C21: =SUM(D21:F21) -> 0 | D21: =+SUMIF(SOFE!$J:$J,'Part IX - Expenses'!$A21,SOFE!E:E) -> 0 | E21: =+SUMIF(SOFE!$J:$J,'Part IX - Expenses'!$A21,SOFE!F:F) -> 0 | F21: =+SUMIF(SOFE!$J:$J,'Part IX - Expenses'!$A21,SOFE!G:G) -> 0 | G21: =+SUMIF(SOFE!K:K,'Part IX - Expenses'!A21,SOFE!I:I) -> 0
A22: 13 | B22: Office Expenses | C22: =SUM(D22:F22) -> 0 | D22: =+SUMIF(SOFE!$J:$J,'Part IX - Expenses'!$A22,SOFE!E:E) -> 0 | E22: =+SUMIF(SOFE!$J:$J,'Part IX - Expenses'!$A22,SOFE!F:F) -> 0 | F22: =+SUMIF(SOFE!$J:$J,'Part IX - Expenses'!$A22,SOFE!G:G) -> 0 | G22: =+SUMIF(SOFE!K:K,'Part IX - Expenses'!A22,SOFE!I:I) -> 0
A23: 14 | B23: Information technology | C23: =SUM(D23:F23) -> 0 | D23: =+SUMIF(SOFE!$J:$J,'Part IX - Expenses'!$A23,SOFE!E:E) -> 0 | E23: =+SUMIF(SOFE!$J:$J,'Part IX - Expenses'!$A23,SOFE!F:F) -> 0 | F23: =+SUMIF(SOFE!$J:$J,'Part IX - Expenses'!$A23,SOFE!G:G) -> 0 | G23: =+SUMIF(SOFE!K:K,'Part IX - Expenses'!A23,SOFE!I:I) -> 0
A24: 15 | B24: Royalties | C24: =SUM(D24:F24) -> 0 | D24: =+SUMIF(SOFE!$J:$J,'Part IX - Expenses'!$A24,SOFE!E:E) -> 0 | E24: =+SUMIF(SOFE!$J:$J,'Part IX - Expenses'!$A24,SOFE!F:F) -> 0 | F24: =+SUMIF(SOFE!$J:$J,'Part IX - Expenses'!$A24,SOFE!G:G) -> 0 | G24: =+SUMIF(SOFE!K:K,'Part IX - Expenses'!A24,SOFE!I:I) -> 0
A25: 16 | B25: Occupancy | C25: =SUM(D25:F25) -> 0 | D25: =+SUMIF(SOFE!$J:$J,'Part IX - Expenses'!$A25,SOFE!E:E) -> 0 | E25: =+SUMIF(SOFE!$J:$J,'Part IX - Expenses'!$A25,SOFE!F:F) -> 0 | F25: =+SUMIF(SOFE!$J:$J,'Part IX - Expenses'!$A25,SOFE!G:G) -> 0 | G25: =+SUMIF(SOFE!K:K,'Part IX - Expenses'!A25,SOFE!I:I) -> 0
A26: 17 | B26: Travel | C26: =SUM(D26:F26) -> 0 | D26: =+SUMIF(SOFE!$J:$J,'Part IX - Expenses'!$A26,SOFE!E:E) -> 0 | E26: =+SUMIF(SOFE!$J:$J,'Part IX - Expenses'!$A26,SOFE!F:F) -> 0 | F26: =+SUMIF(SOFE!$J:$J,'Part IX - Expenses'!$A26,SOFE!G:G) -> 0 | G26: =+SUMIF(SOFE!K:K,'Part IX - Expenses'!A26,SOFE!I:I) -> 0
A27: 18 | B27: Travel/ Entertainment for any federal, state, or local public officials | C27: =SUM(D27:F27) -> 0 | D27: =+SUMIF(SOFE!$J:$J,'Part IX - Expenses'!$A27,SOFE!E:E) -> 0 | E27: =+SUMIF(SOFE!$J:$J,'Part IX - Expenses'!$A27,SOFE!F:F) -> 0 | F27: =+SUMIF(SOFE!$J:$J,'Part IX - Expenses'!$A27,SOFE!G:G) -> 0 | G27: =+SUMIF(SOFE!K:K,'Part IX - Expenses'!A27,SOFE!I:I) -> 0
A28: 19 | B28: Conferences, conventions and meetings | C28: =SUM(D28:F28) -> 0 | D28: =+SUMIF(SOFE!$J:$J,'Part IX - Expenses'!$A28,SOFE!E:E) -> 0 | E28: =+SUMIF(SOFE!$J:$J,'Part IX - Expenses'!$A28,SOFE!F:F) -> 0 | F28: =+SUMIF(SOFE!$J:$J,'Part IX - Expenses'!$A28,SOFE!G:G) -> 0 | G28: =+SUMIF(SOFE!K:K,'Part IX - Expenses'!A28,SOFE!I:I) -> 0
A29: 20 | B29: Interest | C29: =SUM(D29:F29) -> 0 | D29: =+SUMIF(SOFE!$J:$J,'Part IX - Expenses'!$A29,SOFE!E:E) -> 0 | E29: =+SUMIF(SOFE!$J:$J,'Part IX - Expenses'!$A29,SOFE!F:F) -> 0 | F29: =+SUMIF(SOFE!$J:$J,'Part IX - Expenses'!$A29,SOFE!G:G) -> 0 | G29: =+SUMIF(SOFE!K:K,'Part IX - Expenses'!A29,SOFE!I:I) -> 0
A30: 21 | B30: Payments to affiliates | C30: =SUM(D30:F30) -> 0 | D30: =+SUMIF(SOFE!$J:$J,'Part IX - Expenses'!$A30,SOFE!E:E) -> 0 | E30: =+SUMIF(SOFE!$J:$J,'Part IX - Expenses'!$A30,SOFE!F:F) -> 0 | F30: =+SUMIF(SOFE!$J:$J,'Part IX - Expenses'!$A30,SOFE!G:G) -> 0 | G30: =+SUMIF(SOFE!K:K,'Part IX - Expenses'!A30,SOFE!I:I) -> 0
A31: 22 | B31: Depreciation, depletion and amortization | C31: =SUM(D31:F31) -> 0 | D31: =+SUMIF(SOFE!$J:$J,'Part IX - Expenses'!$A31,SOFE!E:E) -> 0 | E31: =+SUMIF(SOFE!$J:$J,'Part IX - Expenses'!$A31,SOFE!F:F) -> 0 | F31: =+SUMIF(SOFE!$J:$J,'Part IX - Expenses'!$A31,SOFE!G:G) -> 0 | G31: =+SUMIF(SOFE!K:K,'Part IX - Expenses'!A31,SOFE!I:I) -> 0
A32: 23 | B32: Insurance | C32: =SUM(D32:F32) -> 0 | D32: =+SUMIF(SOFE!$J:$J,'Part IX - Expenses'!$A32,SOFE!E:E) -> 0 | E32: =+SUMIF(SOFE!$J:$J,'Part IX - Expenses'!$A32,SOFE!F:F) -> 0 | F32: =+SUMIF(SOFE!$J:$J,'Part IX - Expenses'!$A32,SOFE!G:G) -> 0 | G32: =+SUMIF(SOFE!K:K,'Part IX - Expenses'!A32,SOFE!I:I) -> 0
A33: 24 | B33: Other Expenses. Itemize expenses not covered above (List Misc. expenses on 24e and not on lines 24a-d. If line 24e amount exceeds 10% of line 25, column(A) amouont, list line 24e expenses on schedule O) | G33: =+SUMIF(SOFE!K:K,'Part IX - Expenses'!A33,SOFE!I:I) -> 0
A34: 24a | B34: =IFERROR(INDEX(SOFE!$A:$J,MATCH('Part IX - Expenses'!A34,SOFE!$J:$J,0),1),"") | C34: =SUM(D34:F34) -> 0 | D34: =+SUMIF(SOFE!$J:$J,'Part IX - Expenses'!$A34,SOFE!E:E) -> 0 | E34: =+SUMIF(SOFE!$J:$J,'Part IX - Expenses'!$A34,SOFE!F:F) -> 0 | F34: =+SUMIF(SOFE!$J:$J,'Part IX - Expenses'!$A34,SOFE!G:G) -> 0 | G34: =+SUMIF(SOFE!K:K,'Part IX - Expenses'!A34,SOFE!I:I) -> 0
A35: 24b | B35: =IFERROR(INDEX(SOFE!$A:$J,MATCH('Part IX - Expenses'!A35,SOFE!$J:$J,0),1),"") | C35: =SUM(D35:F35) -> 0 | D35: =+SUMIF(SOFE!$J:$J,'Part IX - Expenses'!$A35,SOFE!E:E) -> 0 | E35: =+SUMIF(SOFE!$J:$J,'Part IX - Expenses'!$A35,SOFE!F:F) -> 0 | F35: =+SUMIF(SOFE!$J:$J,'Part IX - Expenses'!$A35,SOFE!G:G) -> 0 | G35: =+SUMIF(SOFE!K:K,'Part IX - Expenses'!A35,SOFE!I:I) -> 0
A36: 24c | B36: =IFERROR(INDEX(SOFE!$A:$J,MATCH('Part IX - Expenses'!A36,SOFE!$J:$J,0),1),"") | C36: =SUM(D36:F36) -> 0 | D36: =+SUMIF(SOFE!$J:$J,'Part IX - Expenses'!$A36,SOFE!E:E) -> 0 | E36: =+SUMIF(SOFE!$J:$J,'Part IX - Expenses'!$A36,SOFE!F:F) -> 0 | F36: =+SUMIF(SOFE!$J:$J,'Part IX - Expenses'!$A36,SOFE!G:G) -> 0 | G36: =+SUMIF(SOFE!K:K,'Part IX - Expenses'!A36,SOFE!I:I) -> 0
A37: 24d | B37: =IFERROR(INDEX(SOFE!$A:$J,MATCH('Part IX - Expenses'!A37,SOFE!$J:$J,0),1),"") | C37: =SUM(D37:F37) -> 0 | D37: =+SUMIF(SOFE!$J:$J,'Part IX - Expenses'!$A37,SOFE!E:E) -> 0 | E37: =+SUMIF(SOFE!$J:$J,'Part IX - Expenses'!$A37,SOFE!F:F) -> 0 | F37: =+SUMIF(SOFE!$J:$J,'Part IX - Expenses'!$A37,SOFE!G:G) -> 0 | G37: =+SUMIF(SOFE!K:K,'Part IX - Expenses'!A37,SOFE!I:I) -> 0
A38: 24e | B38: All Other | C38: =SUM(D38:F38) -> 0 | D38: =+SUMIF(SOFE!$J:$J,'Part IX - Expenses'!$A38,SOFE!E:E) -> 0 | E38: =+SUMIF(SOFE!$J:$J,'Part IX - Expenses'!$A38,SOFE!F:F) -> 0 | F38: =+SUMIF(SOFE!$J:$J,'Part IX - Expenses'!$A38,SOFE!G:G) -> 0 | G38: =+SUMIF(SOFE!K:K,'Part IX - Expenses'!A38,SOFE!I:I) -> 0
A39: 25 | B39: Total Functional Expenses | C39: =SUM(C4:C38) -> 0 | D39: =SUM(D4:D38) -> 0 | E39: =SUM(E4:E38) -> 0 | F39: =SUM(F4:F38) -> 0 | G39: =SUM(G4:G38) -> 0

Sheet Part X - Balance Sheet
A2: Part X - Balance Sheet
B3: Line | C3: Particulars | D3: Beginning of year | E3: End of Year
A4: Assets | B4: 1 | C4: Cash - Non Interest Bearing | D4: =+SUMIF(SOFP!$E:$E,'Part X - Balance Sheet'!B4,SOFP!$C:$C) -> 0 | E4: =+SUMIF(SOFP!$F:$F,'Part X - Balance Sheet'!B4,SOFP!$D:$D) -> 0
B5: 2 | C5: Saving and Temporary Cash Investments | D5: =+SUMIF(SOFP!$E:$E,'Part X - Balance Sheet'!B5,SOFP!$C:$C) -> 0 | E5: =+SUMIF(SOFP!$F:$F,'Part X - Balance Sheet'!B5,SOFP!$D:$D) -> 0
B6: 3 | C6: Pledges and grants receivable, net | D6: =+SUMIF(SOFP!$E:$E,'Part X - Balance Sheet'!B6,SOFP!$C:$C) -> 0 | E6: =+SUMIF(SOFP!$F:$F,'Part X - Balance Sheet'!B6,SOFP!$D:$D) -> 0
B7: 4 | C7: Accounts Receivable, net | D7: =+SUMIF(SOFP!$E:$E,'Part X - Balance Sheet'!B7,SOFP!$C:$C) -> 0 | E7: =+SUMIF(SOFP!$F:$F,'Part X - Balance Sheet'!B7,SOFP!$D:$D) -> 0
B8: 5 | C8: Receivables from Current and Former Officers, Directors, Trustees, Key Employees, creator or founder, substantial contributor, or 35% controlled entity or family member of any of these persons (Sch. L) | D8: =+SUMIF(SOFP!$E:$E,'Part X - Balance Sheet'!B8,SOFP!$C:$C) -> 0 | E8: =+SUMIF(SOFP!$F:$F,'Part X - Balance Sheet'!B8,SOFP!$D:$D) -> 0
B9: 6 | C9: Receivables from other Disqulified Persons | D9: =+SUMIF(SOFP!$E:$E,'Part X - Balance Sheet'!B9,SOFP!$C:$C) -> 0 | E9: =+SUMIF(SOFP!$F:$F,'Part X - Balance Sheet'!B9,SOFP!$D:$D) -> 0
B10: 7 | C10: Notes and Loans Receivable, net | D10: =+SUMIF(SOFP!$E:$E,'Part X - Balance Sheet'!B10,SOFP!$C:$C) -> 0 | E10: =+SUMIF(SOFP!$F:$F,'Part X - Balance Sheet'!B10,SOFP!$D:$D) -> 0
B11: 8 | C11: Inventories for sale or use | D11: =+SUMIF(SOFP!$E:$E,'Part X - Balance Sheet'!B11,SOFP!$C:$C) -> 0 | E11: =+SUMIF(SOFP!$F:$F,'Part X - Balance Sheet'!B11,SOFP!$D:$D) -> 0
B12: 9 | C12: Prepaid Expenses and Deferred Charges | D12: =+SUMIF(SOFP!$E:$E,'Part X - Balance Sheet'!B12,SOFP!$C:$C) -> 0 | E12: =+SUMIF(SOFP!$F:$F,'Part X - Balance Sheet'!B12,SOFP!$D:$D) -> 0
B13: 10a | C13: Land, Buildings and Equipment | D13: =+SUMIF(SOFP!$E:$E,'Part X - Balance Sheet'!B13,SOFP!$C:$C) -> 0 | E13: =+SUMIF(SOFP!$F:$F,'Part X - Balance Sheet'!B13,SOFP!$D:$D) -> 0
B14: 10b | C14: Less: Accumulated Depriciation | D14: =+SUMIF(SOFP!$E:$E,'Part X - Balance Sheet'!B14,SOFP!$C:$C) -> 0 | E14: =+SUMIF(SOFP!$F:$F,'Part X - Balance Sheet'!B14,SOFP!$D:$D) -> 0
C15: Land, Buildings and Equipment - Net | D15: =+D13-D14 -> 0 | E15: =+E13-E14 -> 0
B16: 11 | C16: Investments - Publicly Traded Securities | D16: =+SUMIF(SOFP!$E:$E,'Part X - Balance Sheet'!B16,SOFP!$C:$C) -> 0 | E16: =+SUMIF(SOFP!$F:$F,'Part X - Balance Sheet'!B16,SOFP!$D:$D) -> 0
B17: 12 | C17: Investments - OtherSecurities | D17: =+SUMIF(SOFP!$E:$E,'Part X - Balance Sheet'!B17,SOFP!$C:$C) -> 0 | E17: =+SUMIF(SOFP!$F:$F,'Part X - Balance Sheet'!B17,SOFP!$D:$D) -> 0
B18: 13 | C18: Investments - Program related | D18: =+SUMIF(SOFP!$E:$E,'Part X - Balance Sheet'!B18,SOFP!$C:$C) -> 0 | E18: =+SUMIF(SOFP!$F:$F,'Part X - Balance Sheet'!B18,SOFP!$D:$D) -> 0
B19: 14 | C19: Intangible Assets | D19: =+SUMIF(SOFP!$E:$E,'Part X - Balance Sheet'!B19,SOFP!$C:$C) -> 0 | E19: =+SUMIF(SOFP!$F:$F,'Part X - Balance Sheet'!B19,SOFP!$D:$D) -> 0
B20: 15 | C20: Other assets | D20: =+SUMIF(SOFP!$E:$E,'Part X - Balance Sheet'!B20,SOFP!$C:$C) -> 0 | E20: =+SUMIF(SOFP!$F:$F,'Part X - Balance Sheet'!B20,SOFP!$D:$D) -> 0
B21: 16 | C21: Total Assets | D21: =SUM(D4:D12,D15:D20) -> 0 | E21: =SUM(E4:E12,E15:E20) -> 0
A22: Liabilities | B22: 17 | C22: Accounts Payable and Accrued Expenses | D22: =+SUMIF(SOFP!$E:$E,'Part X - Balance Sheet'!B22,SOFP!$C:$C) -> 0 | E22: =+SUMIF(SOFP!$F:$F,'Part X - Balance Sheet'!B22,SOFP!$D:$D) -> 0
B23: 18 | C23: Grants Payable | D23: =+SUMIF(SOFP!$E:$E,'Part X - Balance Sheet'!B23,SOFP!$C:$C) -> 0 | E23: =+SUMIF(SOFP!$F:$F,'Part X - Balance Sheet'!B23,SOFP!$D:$D) -> 0
B24: 19 | C24: Deferred Revenue | D24: =+SUMIF(SOFP!$E:$E,'Part X - Balance Sheet'!B24,SOFP!$C:$C) -> 0 | E24: =+SUMIF(SOFP!$F:$F,'Part X - Balance Sheet'!B24,SOFP!$D:$D) -> 0
B25: 20 | C25: Tax-Exempt Bond Liabilities | D25: =+SUMIF(SOFP!$E:$E,'Part X - Balance Sheet'!B25,SOFP!$C:$C) -> 0 | E25: =+SUMIF(SOFP!$F:$F,'Part X - Balance Sheet'!B25,SOFP!$D:$D) -> 0
B26: 21 | C26: Escrow or custodial account liability | D26: =+SUMIF(SOFP!$E:$E,'Part X - Balance Sheet'!B26,SOFP!$C:$C) -> 0 | E26: =+SUMIF(SOFP!$F:$F,'Part X - Balance Sheet'!B26,SOFP!$D:$D) -> 0
B27: 22 | C27: Payables to current or former Officers, Directors, Trustees and Key Employees, Highest compensated employees and disqualified persons | D27: =+SUMIF(SOFP!$E:$E,'Part X - Balance Sheet'!B27,SOFP!$C:$C) -> 0 | E27: =+SUMIF(SOFP!$F:$F,'Part X - Balance Sheet'!B27,SOFP!$D:$D) -> 0
B28: 23 | C28: Secured Mortgages and Notes Payable to unrelated third parties | D28: =+SUMIF(SOFP!$E:$E,'Part X - Balance Sheet'!B28,SOFP!$C:$C) -> 0 | E28: =+SUMIF(SOFP!$F:$F,'Part X - Balance Sheet'!B28,SOFP!$D:$D) -> 0
B29: 24 | C29: Unsecured notes and loans payable to unrelated third parties | D29: =+SUMIF(SOFP!$E:$E,'Part X - Balance Sheet'!B29,SOFP!$C:$C) -> 0 | E29: =+SUMIF(SOFP!$F:$F,'Part X - Balance Sheet'!B29,SOFP!$D:$D) -> 0
B30: 25 | C30: Other Liabilities (incl. federal income tax, payables to related thord parties and other liabilities not included above) | D30: =+SUMIF(SOFP!$E:$E,'Part X - Balance Sheet'!B30,SOFP!$C:$C) -> 0 | E30: =+SUMIF(SOFP!$F:$F,'Part X - Balance Sheet'!B30,SOFP!$D:$D) -> 0
B31: 26 | C31: Total Liabilities | D31: =+SUM(D22:D30) -> 0 | E31: =+SUM(E22:E30) -> 0
A32: Net Assets or fund balances | C32: Organizations that follow FASB ASC 958, complete lines 27, 28, 32, and 33
B33: 27 | C33: Net assets without donor restrictions | D33: =+SUMIF(SOFP!$E:$E,'Part X - Balance Sheet'!B33,SOFP!$C:$C) -> 0 | E33: =+SUMIF(SOFP!$F:$F,'Part X - Balance Sheet'!B33,SOFP!$D:$D) -> 0
B34: 28 | C34: Net assets with donor restrictions | D34: =+SUMIF(SOFP!$E:$E,'Part X - Balance Sheet'!B34,SOFP!$C:$C) -> 0 | E34: =+SUMIF(SOFP!$F:$F,'Part X - Balance Sheet'!B34,SOFP!$D:$D) -> 0
C35: Organizations that do not follow FASB ASC 958, complete lines 29 through 33.
B36: 29 | C36: Capital Stock or trust principal or current funds | D36: =+SUMIF(SOFP!$E:$E,'Part X - Balance Sheet'!B36,SOFP!$C:$C) -> 0 | E36: =+SUMIF(SOFP!$F:$F,'Part X - Balance Sheet'!B36,SOFP!$D:$D) -> 0
B37: 30 | C37: Paid in or Capital Surplus, or land, building, or equipment funds | D37: =+SUMIF(SOFP!$E:$E,'Part X - Balance Sheet'!B37,SOFP!$C:$C) -> 0 | E37: =+SUMIF(SOFP!$F:$F,'Part X - Balance Sheet'!B37,SOFP!$D:$D) -> 0
B38: 31 | C38: Retained Earnings, endowment, accumulated income, or other funds | D38: =+SUMIF(SOFP!$E:$E,'Part X - Balance Sheet'!B38,SOFP!$C:$C) -> 0 | E38: =+SUMIF(SOFP!$F:$F,'Part X - Balance Sheet'!B38,SOFP!$D:$D) -> 0
B39: 32 | C39: Total Net Assets or Fund Balances | D39: =SUM(D33:D38) -> 0 | E39: =SUM(E33:E38) -> 0
B40: 33 | C40: Total Liabilities and Net Assets or Fund Balances | D40: =D31+D39 -> 0 | E40: =E31+E39 -> 0
D42: =+D21-D40 -> 0 | E42: =+E21-E40 -> 0 | F42: Check

Sheet Part XI - Net Asset Recon.
A2: Schedule D, Part XI - Recon. Of Revenue per AFS with Form 990
A3: Particulars | B3: Amount
A4: Total Revenue per AFS | B4: =+B14+B10-B13 -> 0
A6: a. New Unrealized Gains (losses) on Investments | B6: =+SUMIF(SOR!F:F,'Part XI - Net Asset Recon.'!C6,SOR!B:B) -> 0 | C6: Adj-UG
A7: b. Donated Services and use of facilities | B7: =+SUMIF(SOR!F:F,'Part XI - Net Asset Recon.'!C7,SOR!B:B) -> 0 | C7: Adj-DS
A8: c. Recoveries of Prior year Grants | B8: =+SUMIF(SOR!F:F,'Part XI - Net Asset Recon.'!C8,SOR!B:B) -> 0 | C8: Adj-PY
A9: d. Other | B9: =+SUMIF(SOR!F:F,'Part XI - Net Asset Recon.'!C9,SOR!B:B) -> 0 | C9: Adj-Other
B10: =+SUM(B6:B9) -> 0
A11: a. Investment Expenses not included on Form 990, Part VIII, line 7b | B11: =+SUMIF(SOR!F:F,'Part XI - Net Asset Recon.'!C11,SOR!B:B) -> 0 | C11: Adj-IE
A12: b. Other | B12: 0
B13: =+SUM(B11:B12) -> 0
A14: Total Revenue (Part VIII , Line 12) | B14: =+'Part VIII - Revenue'!E48 -> 0
A17: Schedule D, Part XII - Recon. Of Expenses per AFS with Form 990
A18: Particulars | B18: Amount
A19: Total Expenses as per AFS | B19: =+B29+B25-B28 -> 0
A21: a. Donated Services and use of facilities | B21: =+SUMIF(SOFE!J:J,'Part XI - Net Asset Recon.'!C21,SOFE!H:H) -> 0 | C21: Adj-DS
A22: b. PY Adjustments | B22: =+SUMIF(SOFE!J:J,'Part XI - Net Asset Recon.'!C22,SOFE!H:H) -> 0 | C22: Adj-PY
A23: c. Other Losses | B23: =+SUMIF(SOFE!J:J,'Part XI - Net Asset Recon.'!C23,SOFE!H:H) -> 0 | C23: Adj-Other Loss
A24: d. Other | B24: =+SUMIF(SOFE!J:J,'Part XI - Net Asset Recon.'!C24,SOFE!H:H) -> 0 | C24: Adj-Other
B25: =+SUM(B21:B24) -> 0
A26: a. Investment Expenses not included on Form 990, Part VIII, line 7b | B26: =+SUMIF(SOFE!J:J,'Part XI - Net Asset Recon.'!C26,SOFE!H:H) -> 0 | C26: Adj-IE
A27: b. Other | B27: 0
B28: =+SUM(B26:B27) -> 0
A29: Total Expenses (Part IX , Line 25) | B29: =+'Part IX - Expenses'!C39 -> 0
A33: Part XI - Reconciliation of Net Assets
A34: Particulars | B34: Amount
A35: 1. Total Revenue (must equal Part VIII, Column (A), line 12) | B35: =+'Part VIII - Revenue'!E48 -> 0
A36: 2. Total expenses (must equal Part IX, column (A), line 25) | B36: =+'Part IX - Expenses'!C39 -> 0
A37: 3. Revenue less expenses. Subtract line 2 from line 1 | B37: =B35-B36 -> 0
A38: 4. Net assets or fund balances at beginning of year (must equal Part X, line 32, column (A)) | B38: =+'Part X - Balance Sheet'!D39 -> 0
A39: 5. Net unrealized gains (losses) on investments | B39: =+B6 -> 0 | C39: Adj-UG
A40: 6. Donated services and use of facilities | B40: =+IF(B7=B21,B7-B21,B7) -> 0 | C40: Adj-DS
A41: 7. Investment expenses | B41: 0 | C41: Adj-IE
A42: 8. Prior period adjustments | B42: =+IF(B8=B22,B8-B22,B8) -> 0 | C42: Adj-PY
A43: 9. Other changes in net assets or fund balances | B43: =+IF(B9=B24,B9,SUM(B9+B24)) -> 0
A44: 10. Net assets or fund balances at end of year. Combine lines 3 through 9 (must equal Part X, line 32, column (B)) | B44: =+SUM(B37:B43) -> 0
A46: Check | B46: =+B44-'Part X - Balance Sheet'!E39 -> 0

Sheet Queries
A1: Sr. No. | B1: Preparer / Reviewer Name | C1: Topic | D1: Comments | E1: Resolution
H4: Name | I4: Date
G5: Preparer
G6: Reviewer 1
G7: Reviewer 2
G8: Reviewer 3
G9: Final Reviewer

Sheet TB Mapping

Sheet SOR
A3: Particulars | B3: Amount (CY) | C3: Related | D3: Unrelated | E3: Excluded in 512-514 | F3: 990 Mapping (CY) | G3: Amount (LY) | H3: 990 Mapping (LY)
A18: Total (As per Audit Report) | B18: =SUM(B4:B17) -> 0 | C18: =SUM(C4:C17) -> 0 | D18: =SUM(D4:D17) -> 0 | E18: =SUM(E4:E17) -> 0 | G18: =SUM(G4:G17) -> 0
A19: * If you have bifurcated any head below, Don't Map in the above statement, Mapping should be done below only
A20: * DO NOT USE CUT (CRTL+X)

Sheet SOFE
B2: PROGRAM SERVICES | F2: SUPPORTING SERVICES
A3: Particulars | B3: Program Services | C3: Support Services | D3: Health Services | E3: PROGRAM SERVICES | F3: Management | G3: Fundraising | H3: Total (CY) | I3: Total (LY) | J3: 990 Mapping (CY) | K3: 990 Mapping (LY)
E4: =+SUM(B4:D4) -> 0 | H4: =+SUM(E4:G4) -> 0
E5: =+SUM(B5:D5) -> 0 | H5: =+SUM(E5:G5) -> 0
E6: =+SUM(B6:D6) -> 0 | H6: =+SUM(E6:G6) -> 0
E7: =+SUM(B7:D7) -> 0 | H7: =+SUM(E7:G7) -> 0
E8: =+SUM(B8:D8) -> 0 | H8: =+SUM(E8:G8) -> 0
E9: =+SUM(B9:D9) -> 0 | H9: =+SUM(E9:G9) -> 0
E10: =+SUM(B10:D10) -> 0 | H10: =+SUM(E10:G10) -> 0
E11: =+SUM(B11:D11) -> 0 | H11: =+SUM(E11:G11) -> 0
E12: =+SUM(B12:D12) -> 0 | H12: =+SUM(E12:G12) -> 0
E13: =+SUM(B13:D13) -> 0 | H13: =+SUM(E13:G13) -> 0
E14: =+SUM(B14:D14) -> 0 | H14: =+SUM(E14:G14) -> 0
E15: =+SUM(B15:D15) -> 0 | H15: =+SUM(E15:G15) -> 0
... E21: =+SUM(B21:D21) -> 0 | H21: =+SUM(E21:G21) -> 0
A22: TOTAL (As Per Audit Report) | B22: =+SUM(B4:B21) -> 0 | C22: =+SUM(C4:C21) -> 0 | D22: =SUM(D4:D21) -> 0 | E22: =SUM(E4:E21) -> 0 | F22: =SUM(F4:F21) -> 0 | G22: =SUM(G4:G21) -> 0 | H22: =SUM(H4:H21) -> 0 | I22: =SUM(I4:I21) -> 0
A23: * If you have bifurcated any head below, Don't Map in the above statement, Mapping should be done below only
A24: * DO NOT USE CUT (CRTL+X)
A26: Total Salaries and Benefits
A27: Compensation to Officer | E27: =+Compensation!G9 -> 0 | F27: =+Compensation!H9 -> 0 | G27: =+Compensation!I9 -> 0 | H27: =+SUM(E27:G27) -> 0 | J27: 5
A28: Other Salaries | E28: =+Compensation!L5 -> 0 | F28: =+Compensation!M5 -> 0 | G28: =+Compensation!N5 -> 0 | H28: =+SUM(E28:G28) -> 0 | J28: 7
A29: Pension | E29: =+Compensation!L6 -> 0 | F29: =+Compensation!M6 -> 0 | G29: =+Compensation!N6 -> 0 | H29: =+SUM(E29:G29) -> 0 | J29: 8
A30: Other Benefits | E30: =+Compensation!L7 -> 0 | F30: =+Compensation!M7 -> 0 | G30: =+Compensation!N7 -> 0 | H30: =+SUM(E30:G30) -> 0 | J30: 9
A31: Payroll Taxes | E31: =+Compensation!L8 -> 0 | F31: =+Compensation!M8 -> 0 | G31: =+Compensation!N8 -> 0 | H31: =+SUM(E31:G31) -> 0 | J31: 10
A32: Total | E32: =SUM(E27:E31) -> 0 | F32: =SUM(F27:F31) -> 0 | G32: =SUM(G27:G31) -> 0 | H32: =SUM(H27:H31) -> 0 | I32: =SUM(I27:I31) -> 0

Sheet Compensation
A1: Compensation Working
A3: Total Salaries and Benefits (as per audit report) | G3: Officer, Director Salaries and Benefits | L3: Remaining Salaries and Benefits
B4: Program Exp | C4: Management & General | D4: Fundraising | E4: Total | G4: Program Exp | H4: Management & General | I4: Fundraising | J4: Total | L4: Program Exp | M4: Management & General | N4: Fundraising | O4: Total
A5: Salaries | B5: 0 | E5: =SOFE!H68 -> 0 | L5: =+B5-G5 -> 0 | M5: =+C5-H5 -> 0 | N5: =+D5-I5 -> 0 | O5: =+SUM(L5:N5) -> 0
A6: Pension Plan | B6: 0 | L6: =+B6-G6 -> 0 | M6: =+C6-H6 -> 0 | N6: =+D6-I6 -> 0 | O6: =+SUM(L6:N6) -> 0
A7: Other Benefits | L7: =+B7-G7 -> 0 | M7: =+C7-H7 -> 0 | N7: =+D7-I7 -> 0 | O7: =+SUM(L7:N7) -> 0
A8: Payroll Taxes | L8: =+B8-G8 -> 0 | M8: =+C8-H8 -> 0 | N8: =+D8-I8 -> 0 | O8: =+SUM(L8:N8) -> 0
A9: Total | B9: =+SUM(B5:B8) -> 0 | C9: =+SUM(C5:C8) -> 0 | D9: =+SUM(D5:D8) -> 0 | E9: =+SUM(E5:E8) -> 0 | G9: =+SUM(G5:G8) -> 0 | H9: =+SUM(H5:H8) -> 0 | I9: =+SUM(I5:I8) -> 0 | J9: =+SUM(J5:J8) -> 0 | L9: =+SUM(L5:L8) -> 0 | M9: =+SUM(M5:M8) -> 0 | N9: =+SUM(N5:N8) -> 0 | O9: =+SUM(O5:O8) -> 0
A12: Schedule Template
A13: Officer | B13: Base Contribution | C13: Benefits | D13: Pension Plan | E13: Total

Sheet CA Rollforward
A1: * DO NOT USE CUT (CRTL+X)

Sheet SOFP
B2: STATEMENT OF FINANCIAL POSITION
B3: Particulars | C3: 2023 | D3: 2024 | E3: 990 Mapping (LY) | F3: 990 Mapping (CY)
B4: Assets
B5: Current assets
B6: Cash and cash equivalents
B7: Investments
B8: Grants receivables
B9: Prepaid Expenses
B10: Security Deposit
B11: Other current assets
B12: Total current assets | C12: =+SUM(C6:C11) -> 0 | D12: =SUM(D6:D11) -> 0
B14: Noncurrent assets
B15: Property and Equipment, net | C15: =+C41 -> 0 | D15: =+D41 -> 0 | E15: Refer to below Working | F15: Refer to below Working
B17: Total noncurrent assets | C17: =SUM(C15) -> 0 | D17: =SUM(D15) -> 0
B19: Total Assets | C19: =+C17+C12 -> 0 | D19: =D12+D17 -> 0
B21: LIABILITIES AND NET ASSETS
B22: LIABILITIES
B23: Current liabilities
B24: Accounts Payable and Accrued Expenses
B25: PPP Loan
B26: Payroll and related Liabilities
B27: Total current liabilities | C27: =+SUM(C24:C26) -> 0 | D27: =+SUM(D24:D26) -> 0
B28: Total Liabilities | C28: =SUM(C27) -> 0 | D28: =SUM(D27) -> 0
B30: NET ASSETS
B31: Without donor restrictions
B32: With donor restrictions
B33: Total Net Assets | C33: =+C31+C32 -> 0 | D33: =+D31+D32 -> 0
B34: Total liabilities and net assets | C34: =C28+C33 -> 0 | D34: =D28+D33 -> 0
B35: * If you have bifurcated any head below, Don't Map in the above statement, Mapping should be done below only
B36: * DO NOT USE CUT (CRTL+X)
B38: Fixed Assets:
B39: Cost | E39: 10a | F39: 10a
B40: less: Accumulated Depreciation | E40: 10b | F40: 10b
B41: Net Fixed Assets | C41: =+C39-C40 -> 0 | D41: =+D39-D40 -> 0
