Workbook
Name Beginning: #REF!
Name BudgetPercentage: #REF!
Name BudgetThreshold: #REF!
Name Client: #REF!
Name Current: #REF!
Name QBCANSUPPORTUPDATE: TRUE
Name QBCANSUPPORTUPDATE: TRUE
Name QBCANSUPPORTUPDATE: TRUE
Name QBCOMPANYFILENAME: "I:\Jewish Family Services.QBW"
Name QBCOMPANYFILENAME: "C:\ElCentroWorkingArchive\libertad.qbw"
Name QBCOMPANYFILENAME: "C:\ElCentroWorkingArchive\libertad.qbw"
Name QBENDDATE: 20240630
Name QBENDDATE: 20220630
Name QBENDDATE: 20220630
Name QBHEADERSONSCREEN: FALSE
Name QBHEADERSONSCREEN: FALSE
Name QBHEADERSONSCREEN: FALSE
Name QBMETADATASIZE: 5931
Name QBMETADATASIZE: 5924
Name QBMETADATASIZE: 5924
Name QBPRESERVECOLOR: TRUE
Name QBPRESERVECOLOR: TRUE
Name QBPRESERVECOLOR: TRUE
Name QBPRESERVEFONT: TRUE
Name QBPRESERVEFONT: TRUE
Name QBPRESERVEFONT: TRUE
Name QBPRESERVEROWHEIGHT: TRUE
Name QBPRESERVEROWHEIGHT: TRUE
Name QBPRESERVEROWHEIGHT: TRUE
Name QBPRESERVESPACE: TRUE
Name QBPRESERVESPACE: FALSE
Name QBPRESERVESPACE: FALSE
Name QBREPORTCOLAXIS: 19
Name QBREPORTCOLAXIS: 8
Name QBREPORTCOLAXIS: 0
Name QBREPORTCOMPANYID: "1299d3132f084724aff0cb21db4a24c4"
Name QBREPORTCOMPANYID: "865a3afdace341f0871aaf9656bcdc8e"
Name QBREPORTCOMPANYID: "865a3afdace341f0871aaf9656bcdc8e"
Name QBREPORTCOMPARECOL_ANNUALBUDGET: FALSE
Name QBREPORTCOMPARECOL_ANNUALBUDGET: FALSE
Name QBREPORTCOMPARECOL_ANNUALBUDGET: FALSE
Name QBREPORTCOMPARECOL_AVGCOGS: FALSE
Name QBREPORTCOMPARECOL_AVGCOGS: FALSE
Name QBREPORTCOMPARECOL_AVGCOGS: FALSE
Name QBREPORTCOMPARECOL_AVGPRICE: FALSE
Name QBREPORTCOMPARECOL_AVGPRICE: FALSE
Name QBREPORTCOMPARECOL_AVGPRICE: FALSE
Name QBREPORTCOMPARECOL_BUDDIFF: FALSE
Name QBREPORTCOMPARECOL_BUDDIFF: FALSE
Name QBREPORTCOMPARECOL_BUDDIFF: FALSE
Name QBREPORTCOMPARECOL_BUDGET: FALSE
Name QBREPORTCOMPARECOL_BUDGET: FALSE
Name QBREPORTCOMPARECOL_BUDGET: FALSE
Name QBREPORTCOMPARECOL_BUDPCT: FALSE
Name QBREPORTCOMPARECOL_BUDPCT: FALSE
Name QBREPORTCOMPARECOL_BUDPCT: FALSE
Name QBREPORTCOMPARECOL_COGS: FALSE
Name QBREPORTCOMPARECOL_COGS: FALSE
Name QBREPORTCOMPARECOL_COGS: FALSE
Name QBREPORTCOMPARECOL_EXCLUDEAMOUNT: FALSE

Sheet Review-Checkpoints
B2: Checklist for Review Exempt Org Tax Return
B4: Revenue - Checks
B5: S No | C5: Check Points | D5: Verification Check | E5: Review Points | F5: Compliance Check
B6: 1 | C6: Is there any Govt Grant | D6: =IF('Part VIII - Revenue'!D8>0,"Yes","No") -> Yes | E6: Is Contributed list updated in Schedule B and RRF-1
B7: 2 | C7: Is there any other contribution | D7: =IF('Part VIII - Revenue'!D9>0,"Yes","No") -> Yes | E7: Is Contributed list updated in Schedule B
B8: 3 | C8: Is there any Non cash contribution more than $25000 | D8: =IF('Part VIII - Revenue'!D10>25000,"Yes","No") -> No | E8: Are details updated in Schedule M
B9: 4 | C9: Is there any donated services / In-Kind service | D9: =IF(ISNUMBER(MATCH("Adj-DS",SOR!F:F, 0)), "Yes", "No") -> Yes | E9: Is it part of reconciliation on page -12 and schedule D
B10: 5 | C10: Is there any Unrealized Gain / Loss | D10: =IF(ISNUMBER(MATCH("Adj-UG",SOR!F:F, 0)), "Yes", "No") -> Yes | E10: Is it part of reconciliation on page -12 and schedule D
B11: 6 | C11: Is there any Program Service Revenue | D11: =IF('Part VIII - Revenue'!E19>0,"Yes","No") -> Yes | E11: Is it reconciled with Page 2
B12: 7 | C12: Is there any Investment Income | D12: =IF('Part VIII - Revenue'!E20>0,"Yes","No") -> Yes | E12: It should be Gross income without effect of Unrealized gain and Investment Exp
B13: 8 | C13: Is there any Investment Management Exp | D13: =IF('Part IX - Expenses'!C19>0,"Yes","No") -> Yes | E13: Is it showing in Line 11f of part IX
B14: 9 | C14: Is there Fundraising Income More Than $15000 | D14: =+IF(('Part VIII - Revenue'!D6+'Part VIII - Revenue'!D33)>15000,"Yes","No") -> Yes | E14: Is Schedule G Filled properly
B17: Expenses - Checks
B18: S No | C18: Check Points | D18: Verification Check | E18: Review Points | F18: Compliance Check
B19: 1 | C19: Is there any Grants and Other Assistance paid more than $5000 | D19: =IF(OR('Part IX - Expenses'!C4>5000, 'Part IX - Expenses'!C5>5000), "Yes", "No") -> Yes | E19: Is Schedule I Filled Properly
B20: 2 | C20: Is there Professional Fundraising Services More Than $15000 | D20: =+IF('Part IX - Expenses'!C18>15000,"Yes","No") -> No | E20: Is Schedule G Filled properly
B21: 3 | C21: Is there any Depreciation expenses | D21: =+IF('Part IX - Expenses'!C31>0,"Yes","No") -> Yes | E21: Is Form 3885 or 3885F Filled properly
B22: 4 | C22: Is Total of Program Service Expenses Reconciled with page 2
B25: Balance Sheet - Checks
B26: S No | C26: Check Points | D26: Verification Check | E26: Review Points | F26: Compliance Check
B27: 1 | C27: Is there any receivable from or payable to disqualified person | D27: =+IF(('Part X - Balance Sheet'!E8+'Part X - Balance Sheet'!E27)>0,"Yes","No") -> No | E27: Is Schedule L filled properly and Line 1 of RRF-1 marked yes
B28: 2 | C28: Is there any other transaction with disqualified person | D28: No | E28: Is Schedule L filled properly and Line 1 of RRF-1 marked yes
B29: 3 | C29: Is there any Escrow and Custodial Arrangements | D29: =+IF('Part X - Balance Sheet'!E26>0,"Yes","No") -> No | E29: Is Part IV of Schedule D filled properly
B30: 4 | C30: Is there any fixed assets | D30: =IF('Part X - Balance Sheet'!E15>0,"Yes","No") -> Yes | E30: Is Part VI of schedule D matched with Audit Report
B31: 5 | C31: Is organization hold assets in donor-restricted endowments | D31: No | E31: Is Part V of Schedule D filled properly
B32: 6 | C32: Is there any related party (See Note in Audit Report) | D32: No | E32: Is Schedule R filled properly
B35: Other - Checks
B36: S No | C36: Check Points | D36: Verification Check | E36: Review Points | F36: Compliance Check
B37: 1 | C37: Is all revenue figures updated in schedule A | D37: No
B38: 2 | C38: Is Form-199 figures matched with Audit Report or Books | D38: Yes
B39: 3 | C39: Are figures updated in Form RRF-1 | D39: No
B40: 4 | C40: Is it being submitted per Final Audit Report figures | D40: No | E40: Are these lines marked "✔" (Part IV Line 12a/b, Part XII Line 2a,b,c, RRF-1 Line 8)
B41: 5 | C41: Is there any footnote regarding the uncertain income tax position in the Final Audit Report | D41: No | E41: Is it stated in Schedule D Supplemental Information
B42: 6 | C42: Is single audit applicable in Audit Report (SEFA) | D42: No | E42: Are these lines marked "✔" (Part XII Line 3a and 3b)
B43: 7 | C43: Is the FY ending other than December | D43: No | E43: Is CA copy made and compensation statement generated in form 199.

Sheet Part VIII - Revenue
A2: Part VIII - Statement of Revenue
A3: Line | B3: Particulars | E3: Total Revenue | F3: Related or Exempt Function Income | G3: Unrelated Business Revenue | H3: Revenue excluded from tax under $512, 513 or 514 | I3: Last Year
A4: 1a | B4: Federated Campaigns | D4: =+SUMIF(SOR!$F:$F,'Part VIII - Revenue'!$A4,SOR!$B:$B) -> 0 | I4: =+SUMIF(SOR!$H:$H,'Part VIII - Revenue'!$A4,SOR!$G:$G) -> 0
A5: 1b | B5: Membership Dues | D5: =+SUMIF(SOR!$F:$F,'Part VIII - Revenue'!$A5,SOR!$B:$B) -> 0 | I5: =+SUMIF(SOR!$H:$H,'Part VIII - Revenue'!$A5,SOR!$G:$G) -> 0
A6: 1c | B6: Fundraising Events | D6: =+SUMIF(SOR!$F:$F,'Part VIII - Revenue'!$A6,SOR!$B:$B) -> 152678 | I6: =+SUMIF(SOR!$H:$H,'Part VIII - Revenue'!$A6,SOR!$G:$G) -> 145827
A7: 1d | B7: Related Organisations | D7: =+SUMIF(SOR!$F:$F,'Part VIII - Revenue'!$A7,SOR!$B:$B) -> 0 | I7: =+SUMIF(SOR!$H:$H,'Part VIII - Revenue'!$A7,SOR!$G:$G) -> 0
A8: 1e | B8: Government Grants/ Contributions | D8: =+SUMIF(SOR!$F:$F,'Part VIII - Revenue'!$A8,SOR!$B:$B) -> 2083067 | I8: =+SUMIF(SOR!$H:$H,'Part VIII - Revenue'!$A8,SOR!$G:$G) -> 5311998
A9: 1f | B9: All Other contributions, gifts, grants and similar amounts not listed above | D9: =+SUMIF(SOR!$F:$F,'Part VIII - Revenue'!$A9,SOR!$B:$B)+SUMIF(SOR!$F:$F,'Part VIII - Revenue'!$A10,SOR!$B:$B) -> 8057976 | I9: =+SUMIF(SOR!$H:$H,'Part VIII - Revenue'!$A9,SOR!$G:$G) -> 2829753
A10: 1g | B10: Noncash Contributions included in lines 1a-1f | D10: =+SUMIF(SOR!$F:$F,'Part VIII - Revenue'!$A10,SOR!$B:$B) -> 0 | I10: =+SUMIF(SOR!$H:$H,'Part VIII - Revenue'!$A10,SOR!$G:$G) -> 87636
A11: 1h | B11: Total. Add Lines 1a-1f | E11: =+SUM(D4:D9) -> 10293721 | I11: =SUM(I4:I10) -> 8375214
A12: 2 | B12: Program Service Revenue | D12: Business Code
A13: 2a | B13: =IFERROR(+INDEX(SOR!A:F,MATCH('Part VIII - Revenue'!A13,SOR!F:F,0),1),"") -> Program fees | E13: =SUM(F13:H13) -> 12254 | F13: =+SUMIF(SOR!$F:$F,'Part VIII - Revenue'!$A:$A,SOR!C:C) -> 12254 | G13: =+SUMIF(SOR!$F:$F,'Part VIII - Revenue'!$A:$A,SOR!D:D) -> 0 | H13: =+SUMIF(SOR!$F:$F,'Part VIII - Revenue'!$A:$A,SOR!E:E) -> 0 | I13: =+SUMIF(SOR!$H:$H,'Part VIII - Revenue'!$A13,SOR!$G:$G) -> 42558
A14: 2b | B14: =IFERROR(+INDEX(SOR!A:F,MATCH('Part VIII - Revenue'!A14,SOR!F:F,0),1),"") | E14: =SUM(F14:H14) -> 0 | F14: =+SUMIF(SOR!$F:$F,'Part VIII - Revenue'!$A:$A,SOR!C:C) -> 0 | G14: =+SUMIF(SOR!$F:$F,'Part VIII - Revenue'!$A:$A,SOR!D:D) -> 0 | H14: =+SUMIF(SOR!$F:$F,'Part VIII - Revenue'!$A:$A,SOR!E:E) -> 0 | I14: =+SUMIF(SOR!$H:$H,'Part VIII - Revenue'!$A14,SOR!$G:$G) -> 0
A15: 2c | B15: =IFERROR(+INDEX(SOR!A:F,MATCH('Part VIII - Revenue'!A15,SOR!F:F,0),1),"") | E15: =SUM(F15:H15) -> 0 | F15: =+SUMIF(SOR!$F:$F,'Part VIII - Revenue'!$A:$A,SOR!C:C) -> 0 | G15: =+SUMIF(SOR!$F:$F,'Part VIII - Revenue'!$A:$A,SOR!D:D) -> 0 | H15: =+SUMIF(SOR!$F:$F,'Part VIII - Revenue'!$A:$A,SOR!E:E) -> 0 | I15: =+SUMIF(SOR!$H:$H,'Part VIII - Revenue'!$A15,SOR!$G:$G) -> 0
A16: 2d | B16: =IFERROR(+INDEX(SOR!A:F,MATCH('Part VIII - Revenue'!A16,SOR!F:F,0),1),"") | E16: =SUM(F16:H16) -> 0 | F16: =+SUMIF(SOR!$F:$F,'Part VIII - Revenue'!$A:$A,SOR!C:C) -> 0 | G16: =+SUMIF(SOR!$F:$F,'Part VIII - Revenue'!$A:$A,SOR!D:D) -> 0 | H16: =+SUMIF(SOR!$F:$F,'Part VIII - Revenue'!$A:$A,SOR!E:E) -> 0 | I16: =+SUMIF(SOR!$H:$H,'Part VIII - Revenue'!$A16,SOR!$G:$G) -> 0
A17: 2e | B17: =IFERROR(+INDEX(SOR!A:F,MATCH('Part VIII - Revenue'!A17,SOR!F:F,0),1),"") | E17: =SUM(F17:H17) -> 0 | F17: =+SUMIF(SOR!$F:$F,'Part VIII - Revenue'!$A:$A,SOR!C:C) -> 0 | G17: =+SUMIF(SOR!$F:$F,'Part VIII - Revenue'!$A:$A,SOR!D:D) -> 0 | H17: =+SUMIF(SOR!$F:$F,'Part VIII - Revenue'!$A:$A,SOR!E:E) -> 0 | I17: =+SUMIF(SOR!$H:$H,'Part VIII - Revenue'!$A17,SOR!$G:$G) -> 0
A18: 2f | B18: All other program service revenue | E18: =SUM(F18:H18) -> 0 | F18: =+SUMIF(SOR!$F:$F,'Part VIII - Revenue'!$A:$A,SOR!C:C) -> 0 | G18: =+SUMIF(SOR!$F:$F,'Part VIII - Revenue'!$A:$A,SOR!D:D) -> 0 | H18: =+SUMIF(SOR!$F:$F,'Part VIII - Revenue'!$A:$A,SOR!E:E) -> 0 | I18: =+SUMIF(SOR!$H:$H,'Part VIII - Revenue'!$A18,SOR!$G:$G) -> 0
A19: 2g | B19: Total. Add Lines 2a-2f | E19: =+SUM(E13:E18) -> 12254 | I19: =SUM(I13:I18) -> 42558
A20: 3 | B20: Investment Income (dividends, interest and other similar amounts) | E20: =+SUM(F20:H20) -> 24774 | F20: =+SUMIF(SOR!$F:$F,'Part VIII - Revenue'!$A:$A,SOR!C:C) -> 0 | G20: =+SUMIF(SOR!$F:$F,'Part VIII - Revenue'!$A:$A,SOR!D:D) -> 0 | H20: =+SUMIF(SOR!$F:$F,'Part VIII - Revenue'!$A:$A,SOR!E:E) -> 24774 | I20: =+SUMIF(SOR!$H:$H,'Part VIII - Revenue'!$A20,SOR!$G:$G) -> 29358
A21: 4 | B21: Income from Investment of tax-exempt bond proceeds | E21: =SUM(F21:H21) -> 0 | F21: =+SUMIF(SOR!$F:$F,'Part VIII - Revenue'!$A:$A,SOR!C:C) -> 0 | G21: =+SUMIF(SOR!$F:$F,'Part VIII - Revenue'!$A:$A,SOR!D:D) -> 0 | H21: =+SUMIF(SOR!$F:$F,'Part VIII - Revenue'!$A:$A,SOR!E:E) -> 0 | I21: =+SUMIF(SOR!$H:$H,'Part VIII - Revenue'!$A21,SOR!$G:$G) -> 0
A22: 5 | B22: Royalties | E22: =SUM(F22:H22) -> 0 | F22: =+SUMIF(SOR!$F:$F,'Part VIII - Revenue'!$A:$A,SOR!C:C) -> 0 | G22: =+SUMIF(SOR!$F:$F,'Part VIII - Revenue'!$A:$A,SOR!D:D) -> 0 | H22: =+SUMIF(SOR!$F:$F,'Part VIII - Revenue'!$A:$A,SOR!E:E) -> 0 | I22: =+SUMIF(SOR!$H:$H,'Part VIII - Revenue'!$A22,SOR!$G:$G) -> 0
C23: Real | D23: Personal
A24: 6a | B24: Gross Rents | C24: =+SUMIF(SOR!F:F,"6a-R",SOR!B:B) -> 0 | D24: =+SUMIF(SOR!F:F,"6a-P",SOR!B:B) -> 0 | I24: =+SUMIF(SOR!H:H,"6a-R",SOR!G:G)+SUMIF(SOR!H:H,"6a-P",SOR!G:G) -> 0
A25: 6b | B25: Less: Rental Expenses | C25: =+SUMIF(SOR!F:F,"6b-R",SOR!B:B) -> 0 | D25: =+SUMIF(SOR!F:F,"6b-P",SOR!B:B) -> 0 | I25: =+SUMIF(SOR!H:H,"6b-R",SOR!G:G)+SUMIF(SOR!H:H,"6b-P",SOR!G:G) -> 0
A26: 6c | B26: Rental Income or (Loss) | C26: =+C24-C25 -> 0 | D26: =D24-D25 -> 0 | I26: =+I24-I25 -> 0
A27: 6d | B27: Net Rental Income or (Loss) | E27: =+SUM(F27:H27) -> 0 | F27: =+SUMIF(SOR!F:F,"6a-R",SOR!C:C)-SUMIF(SOR!F:F,"6b-R",SOR!C:C)+SUMIF(SOR!F:F,"6a-P",SOR!C:C)-SUMIF(SOR!F:F,"6b-P",SOR!C:C) -> 0 | G27: =+SUMIF(SOR!F:F,"6a-R",SOR!D:D)-SUMIF(SOR!F:F,"6b-R",SOR!D:D)+SUMIF(SOR!F:F,"6a-P",SOR!D:D)-SUMIF(SOR!F:F,"6b-P",SOR!D:D) -> 0 | H27: =+SUMIF(SOR!F:F,"6a-R",SOR!E:E)-SUMIF(SOR!F:F,"6b-R",SOR!E:E)+SUMIF(SOR!F:F,"6a-P",SOR!E:E)-SUMIF(SOR!F:F,"6b-P",SOR!E:E) -> 0 | I27: =+I26 -> 0
C28: Securities | D28: Other
A29: 7a | B29: Gross Amounts from Sales of Assets other than Inventory | C29: =+SUMIF(SOR!F:F,"7a-S",SOR!B:B) -> 0 | D29: =+SUMIF(SOR!F:F,"7a-O",SOR!B:B) -> 0 | I29: =+SUMIF(SOR!H:H,"7a-S",SOR!G:G)+SUMIF(SOR!H:H,"7a-O",SOR!G:G) -> 103637
A30: 7b | B30: Less: Cost or Other Basis and sales expenses | C30: =+SUMIF(SOR!F:F,"7b-S",SOR!B:B) -> 0 | D30: =+SUMIF(SOR!F:F,"7b-o",SOR!B:B) -> 0 | I30: =+SUMIF(SOR!H:H,"7b-S",SOR!G:G)+SUMIF(SOR!H:H,"7b-O",SOR!G:G) -> 103801
A31: 7c | B31: Gain or (Loss) | C31: =+C29-C30 -> 0 | D31: =+D29-D30 -> 0 | I31: =+I29-I30 -> -164
A32: 7d | B32: Net Gain or (Loss) | E32: =SUM(F32:H32) -> 0 | F32: =+SUMIF(SOR!F:F,"7a-S",SOR!C:C)-SUMIF(SOR!F:F,"7b-S",SOR!C:C)+SUMIF(SOR!F:F,"7a-O",SOR!C:C)-SUMIF(SOR!F:F,"7b-O",SOR!C:C) -> 0 | G32: =+SUMIF(SOR!F:F,"7a-S",SOR!D:D)-SUMIF(SOR!F:F,"7b-S",SOR!D:D)+SUMIF(SOR!F:F,"7a-O",SOR!D:D)-SUMIF(SOR!F:F,"7b-O",SOR!D:D) -> 0 | H32: =+SUMIF(SOR!F:F,"7a-S",SOR!E:E)-SUMIF(SOR!F:F,"7b-S",SOR!E:E)+SUMIF(SOR!F:F,"7a-O",SOR!E:E)-SUMIF(SOR!F:F,"7b-O",SOR!E:E) -> 0 | I32: =+I31 -> -164
A33: 8a | B33: Gross Income from fundraising activities (not including contributions on line 1c) | D33: =+SUMIF(SOR!F:F,A33,SOR!B:B) -> 48164 | I33: =+SUMIF(SOR!$H:$H,'Part VIII - Revenue'!$A33,SOR!$G:$G) -> 33930
A34: 8b | B34: Less: Direct Expenses | D34: =+SUMIF(SOR!F:F,A34,SOR!B:B) -> 48164 | I34: =+SUMIF(SOR!$H:$H,'Part VIII - Revenue'!$A34,SOR!$G:$G) -> 33930
A35: 8c | B35: Net Income or (loss) from fund raising activities | E35: =+D33-D34 -> 0 | I35: =+I33-I34 -> 0
A36: 9a | B36: Gross Income from Gaming Activities | D36: =+SUMIF(SOR!F:F,A36,SOR!B:B) -> 0 | I36: =+SUMIF(SOR!$H:$H,'Part VIII - Revenue'!$A36,SOR!$G:$G) -> 0
A37: 9b | B37: Less: Direct Expenses | D37: =+SUMIF(SOR!F:F,A37,SOR!B:B) -> 0 | I37: =+SUMIF(SOR!$H:$H,'Part VIII - Revenue'!$A37,SOR!$G:$G) -> 0
A38: 9c | B38: Net Income or (loss) from gaming activities | E38: =SUM(F38:H38) -> 0 | F38: =+SUMIF(SOR!F:F,"9a",SOR!C:C)-SUMIF(SOR!F:F,"9b",SOR!C:C) -> 0 | G38: =+SUMIF(SOR!F:F,"9a",SOR!D:D)-SUMIF(SOR!F:F,"9b",SOR!D:D) -> 0 | H38: =+SUMIF(SOR!F:F,"9a",SOR!E:E)-SUMIF(SOR!F:F,"9b",SOR!E:E) -> 0 | I38: =+I36-I37 -> 0
A39: 10a | B39: Gross Sales of Inventory, less returns and allowances | D39: =+SUMIF(SOR!F:F,A39,SOR!B:B) -> 0 | I39: =+SUMIF(SOR!$H:$H,'Part VIII - Revenue'!$A39,SOR!$G:$G) -> 0
A40: 10b | B40: Less: COGS | D40: =+SUMIF(SOR!F:F,A40,SOR!B:B) -> 0 | I40: =+SUMIF(SOR!$H:$H,'Part VIII - Revenue'!$A40,SOR!$G:$G) -> 0
A41: 10c | B41: Net Income or (loss) from Sales of Inventory | E41: =SUM(F41:H41) -> 0 | F41: =+SUMIF(SOR!F:F,"10a",SOR!C:C)-SUMIF(SOR!F:F,"10b",SOR!C:C) -> 0 | G41: =+SUMIF(SOR!F:F,"10a",SOR!D:D)-SUMIF(SOR!F:F,"10b",SOR!D:D) -> 0 | H41: =+SUMIF(SOR!F:F,"10a",SOR!E:E)-SUMIF(SOR!F:F,"10b",SOR!E:E) -> 0 | I41: =+I39-I40 -> 0
...

Sheet Part IX - Expenses
A2: Part IX: Statement of Functional Expenses
A3: Line | B3: Particulars | C3: Total | D3: Program Service | E3: Management | F3: Fundraising | G3: Last Year
A4: 1 | B4: Grants and other assistance to domestic governments and domestic organisations | C4: =SUM(D4:F4) -> 0 | D4: =+SUMIF(SOFE!$J:$J,'Part IX - Expenses'!$A4,SOFE!E:E) -> 0 | G4: =+SUMIF(SOFE!K:K,'Part IX - Expenses'!A4,SOFE!I:I) -> 0
A5: 2 | B5: Grants and other assistance to domestic individuals | C5: =SUM(D5:F5) -> 6682083 | D5: =+SUMIF(SOFE!$J:$J,'Part IX - Expenses'!$A5,SOFE!E:E) -> 6682083 | G5: =+SUMIF(SOFE!K:K,'Part IX - Expenses'!A5,SOFE!I:I) -> 2346370
A6: 3 | B6: Grants and other assistance foreign organizations, foreign governments and foreign individuals | C6: =SUM(D6:F6) -> 0 | D6: =+SUMIF(SOFE!$J:$J,'Part IX - Expenses'!$A6,SOFE!E:E) -> 0 | G6: =+SUMIF(SOFE!K:K,'Part IX - Expenses'!A6,SOFE!I:I) -> 0
A7: 4 | B7: Benefits paid to or for members | C7: =SUM(D7:F7) -> 0 | D7: =+SUMIF(SOFE!$J:$J,'Part IX - Expenses'!$A7,SOFE!E:E) -> 0 | G7: =+SUMIF(SOFE!K:K,'Part IX - Expenses'!A7,SOFE!I:I) -> 0
A8: 5 | B8: Compensation of Current officers, directors, trustees and key employees | C8: =SUM(D8:F8) -> 222753.79 | D8: =+SUMIF(SOFE!$J:$J,'Part IX - Expenses'!$A8,SOFE!E:E) -> 186012.93 | E8: =+SUMIF(SOFE!$J:$J,'Part IX - Expenses'!$A8,SOFE!F:F) -> 24663.458 | F8: =+SUMIF(SOFE!$J:$J,'Part IX - Expenses'!$A8,SOFE!G:G) -> 12077.404 | G8: =+SUMIF(SOFE!K:K,'Part IX - Expenses'!A8,SOFE!I:I) -> 330716
A9: 6 | B9: Compensations not included above to disqualified persons | C9: =SUM(D9:F9) -> 0 | D9: =+SUMIF(SOFE!$J:$J,'Part IX - Expenses'!$A9,SOFE!E:E) -> 0 | E9: =+SUMIF(SOFE!$J:$J,'Part IX - Expenses'!$A9,SOFE!F:F) -> 0 | F9: =+SUMIF(SOFE!$J:$J,'Part IX - Expenses'!$A9,SOFE!G:G) -> 0 | G9: =+SUMIF(SOFE!K:K,'Part IX - Expenses'!A9,SOFE!I:I) -> 0
A10: 7 | B10: Other Salaries and wages | C10: =SUM(D10:F10) -> 3192052.2 | D10: =+SUMIF(SOFE!$J:$J,'Part IX - Expenses'!$A10,SOFE!E:E) -> 2669445.2 | E10: =+SUMIF(SOFE!$J:$J,'Part IX - Expenses'!$A10,SOFE!F:F) -> 332455.69 | F10: =+SUMIF(SOFE!$J:$J,'Part IX - Expenses'!$A10,SOFE!G:G) -> 190151.27 | G10: =+SUMIF(SOFE!K:K,'Part IX - Expenses'!A10,SOFE!I:I) -> 2245736
A11: 8 | B11: Pension plam accruals & contributions (incl. 401(k) and 403(b) employer contr.) | C11: =SUM(D11:F11) -> 83460.25 | D11: =+SUMIF(SOFE!$J:$J,'Part IX - Expenses'!$A11,SOFE!E:E) -> 69453.697 | E11: =+SUMIF(SOFE!$J:$J,'Part IX - Expenses'!$A11,SOFE!F:F) -> 12373.591 | F11: =+SUMIF(SOFE!$J:$J,'Part IX - Expenses'!$A11,SOFE!G:G) -> 1632.9621 | G11: =+SUMIF(SOFE!K:K,'Part IX - Expenses'!A11,SOFE!I:I) -> 15873
A12: 9 | B12: Other Employee Benefits | C12: =SUM(D12:F12) -> 430582.8 | D12: =+SUMIF(SOFE!$J:$J,'Part IX - Expenses'!$A12,SOFE!E:E) -> 356024.94 | E12: =+SUMIF(SOFE!$J:$J,'Part IX - Expenses'!$A12,SOFE!F:F) -> 63164.242 | F12: =+SUMIF(SOFE!$J:$J,'Part IX - Expenses'!$A12,SOFE!G:G) -> 11393.617 | G12: =+SUMIF(SOFE!K:K,'Part IX - Expenses'!A12,SOFE!I:I) -> 225403
A13: 10 | B13: Payroll taxes | C13: =SUM(D13:F13) -> 272241 | D13: =+SUMIF(SOFE!$J:$J,'Part IX - Expenses'!$A13,SOFE!E:E) -> 252343 | E13: =+SUMIF(SOFE!$J:$J,'Part IX - Expenses'!$A13,SOFE!F:F) -> 12636 | F13: =+SUMIF(SOFE!$J:$J,'Part IX - Expenses'!$A13,SOFE!G:G) -> 7262 | G13: =+SUMIF(SOFE!K:K,'Part IX - Expenses'!A13,SOFE!I:I) -> 197666
A14: 11a | B14: Management | C14: =SUM(D14:F14) -> 0 | D14: =+SUMIF(SOFE!$J:$J,'Part IX - Expenses'!$A14,SOFE!E:E) -> 0 | E14: =+SUMIF(SOFE!$J:$J,'Part IX - Expenses'!$A14,SOFE!F:F) -> 0 | F14: =+SUMIF(SOFE!$J:$J,'Part IX - Expenses'!$A14,SOFE!G:G) -> 0 | G14: =+SUMIF(SOFE!K:K,'Part IX - Expenses'!A14,SOFE!I:I) -> 0
A15: 11b | B15: Legal | C15: =SUM(D15:F15) -> 64263 | D15: =+SUMIF(SOFE!$J:$J,'Part IX - Expenses'!$A15,SOFE!E:E) -> 60483 | E15: =+SUMIF(SOFE!$J:$J,'Part IX - Expenses'!$A15,SOFE!F:F) -> 3780 | F15: =+SUMIF(SOFE!$J:$J,'Part IX - Expenses'!$A15,SOFE!G:G) -> 0 | G15: =+SUMIF(SOFE!K:K,'Part IX - Expenses'!A15,SOFE!I:I) -> 29969.5
A16: 11c | B16: Accounting | C16: =SUM(D16:F16) -> 307745 | D16: =+SUMIF(SOFE!$J:$J,'Part IX - Expenses'!$A16,SOFE!E:E) -> 9990.3298 | E16: =+SUMIF(SOFE!$J:$J,'Part IX - Expenses'!$A16,SOFE!F:F) -> 287545.31 | F16: =+SUMIF(SOFE!$J:$J,'Part IX - Expenses'!$A16,SOFE!G:G) -> 10209.357 | G16: =+SUMIF(SOFE!K:K,'Part IX - Expenses'!A16,SOFE!I:I) -> 150800
A17: 11d | B17: Lobbying | C17: =SUM(D17:F17) -> 0 | D17: =+SUMIF(SOFE!$J:$J,'Part IX - Expenses'!$A17,SOFE!E:E) -> 0 | E17: =+SUMIF(SOFE!$J:$J,'Part IX - Expenses'!$A17,SOFE!F:F) -> 0 | F17: =+SUMIF(SOFE!$J:$J,'Part IX - Expenses'!$A17,SOFE!G:G) -> 0 | G17: =+SUMIF(SOFE!K:K,'Part IX - Expenses'!A17,SOFE!I:I) -> 0
A18: 11e | B18: Professional Fundraising services | C18: =SUM(D18:F18) -> 0 | F18: =+SUMIF(SOFE!$J:$J,'Part IX - Expenses'!$A18,SOFE!G:G) -> 0 | G18: =+SUMIF(SOFE!K:K,'Part IX - Expenses'!A18,SOFE!I:I) -> 0
A19: 11f | B19: Investment Management Fees | C19: =SUM(D19:F19) -> 2167 | D19: =+SUMIF(SOFE!$J:$J,'Part IX - Expenses'!$A19,SOFE!E:E) -> 77.953685 | E19: =+SUMIF(SOFE!$J:$J,'Part IX - Expenses'!$A19,SOFE!F:F) -> 1187.023 | F19: =+SUMIF(SOFE!$J:$J,'Part IX - Expenses'!$A19,SOFE!G:G) -> 902.02329 | G19: =+SUMIF(SOFE!K:K,'Part IX - Expenses'!A19,SOFE!I:I) -> 2070
A20: 11g | B20: Other Fees for service | C20: =SUM(D20:F20) -> 125143 | D20: =+SUMIF(SOFE!$J:$J,'Part IX - Expenses'!$A20,SOFE!E:E) -> 35498.67 | E20: =+SUMIF(SOFE!$J:$J,'Part IX - Expenses'!$A20,SOFE!F:F) -> 67171.687 | F20: =+SUMIF(SOFE!$J:$J,'Part IX - Expenses'!$A20,SOFE!G:G) -> 22472.643 | G20: =+SUMIF(SOFE!K:K,'Part IX - Expenses'!A20,SOFE!I:I) -> 194682.58
A21: 12 | B21: Advertising and promotion | C21: =SUM(D21:F21) -> 2909 | D21: =+SUMIF(SOFE!$J:$J,'Part IX - Expenses'!$A21,SOFE!E:E) -> 1650 | E21: =+SUMIF(SOFE!$J:$J,'Part IX - Expenses'!$A21,SOFE!F:F) -> 1074 | F21: =+SUMIF(SOFE!$J:$J,'Part IX - Expenses'!$A21,SOFE!G:G) -> 185 | G21: =+SUMIF(SOFE!K:K,'Part IX - Expenses'!A21,SOFE!I:I) -> 5810
A22: 13 | B22: Office Expenses | C22: =SUM(D22:F22) -> 250596 | D22: =+SUMIF(SOFE!$J:$J,'Part IX - Expenses'!$A22,SOFE!E:E) -> 135715.05 | E22: =+SUMIF(SOFE!$J:$J,'Part IX - Expenses'!$A22,SOFE!F:F) -> 92446.977 | F22: =+SUMIF(SOFE!$J:$J,'Part IX - Expenses'!$A22,SOFE!G:G) -> 22433.977 | G22: =+SUMIF(SOFE!K:K,'Part IX - Expenses'!A22,SOFE!I:I) -> 137506
A23: 14 | B23: Information technology | C23: =SUM(D23:F23) -> 104996 | D23: =+SUMIF(SOFE!$J:$J,'Part IX - Expenses'!$A23,SOFE!E:E) -> 46484 | E23: =+SUMIF(SOFE!$J:$J,'Part IX - Expenses'!$A23,SOFE!F:F) -> 56404 | F23: =+SUMIF(SOFE!$J:$J,'Part IX - Expenses'!$A23,SOFE!G:G) -> 2108 | G23: =+SUMIF(SOFE!K:K,'Part IX - Expenses'!A23,SOFE!I:I) -> 37237
A24: 15 | B24: Royalties | C24: =SUM(D24:F24) -> 0 | D24: =+SUMIF(SOFE!$J:$J,'Part IX - Expenses'!$A24,SOFE!E:E) -> 0 | E24: =+SUMIF(SOFE!$J:$J,'Part IX - Expenses'!$A24,SOFE!F:F) -> 0 | F24: =+SUMIF(SOFE!$J:$J,'Part IX - Expenses'!$A24,SOFE!G:G) -> 0 | G24: =+SUMIF(SOFE!K:K,'Part IX - Expenses'!A24,SOFE!I:I) -> 0
A25: 16 | B25: Occupancy | C25: =SUM(D25:F25) -> 84206 | D25: =+SUMIF(SOFE!$J:$J,'Part IX - Expenses'!$A25,SOFE!E:E) -> 84666 | E25: =+SUMIF(SOFE!$J:$J,'Part IX - Expenses'!$A25,SOFE!F:F) -> -2758 | F25: =+SUMIF(SOFE!$J:$J,'Part IX - Expenses'!$A25,SOFE!G:G) -> 2298 | G25: =+SUMIF(SOFE!K:K,'Part IX - Expenses'!A25,SOFE!I:I) -> 108136
A26: 17 | B26: Travel | C26: =SUM(D26:F26) -> 15877.14 | D26: =+SUMIF(SOFE!$J:$J,'Part IX - Expenses'!$A26,SOFE!E:E) -> 15531 | E26: =+SUMIF(SOFE!$J:$J,'Part IX - Expenses'!$A26,SOFE!F:F) -> 292.14 | F26: =+SUMIF(SOFE!$J:$J,'Part IX - Expenses'!$A26,SOFE!G:G) -> 54 | G26: =+SUMIF(SOFE!K:K,'Part IX - Expenses'!A26,SOFE!I:I) -> 8526.18
A27: 18 | B27: Travel/ Entertainment for any federal, state, or local public officials | C27: =SUM(D27:F27) -> 0 | D27: =+SUMIF(SOFE!$J:$J,'Part IX - Expenses'!$A27,SOFE!E:E) -> 0 | E27: =+SUMIF(SOFE!$J:$J,'Part IX - Expenses'!$A27,SOFE!F:F) -> 0 | F27: =+SUMIF(SOFE!$J:$J,'Part IX - Expenses'!$A27,SOFE!G:G) -> 0 | G27: =+SUMIF(SOFE!K:K,'Part IX - Expenses'!A27,SOFE!I:I) -> 0
A28: 19 | B28: Conferences, conventions and meetings | C28: =SUM(D28:F28) -> 30788.27 | D28: =+SUMIF(SOFE!$J:$J,'Part IX - Expenses'!$A28,SOFE!E:E) -> 8554.1 | E28: =+SUMIF(SOFE!$J:$J,'Part IX - Expenses'!$A28,SOFE!F:F) -> 12479.17 | F28: =+SUMIF(SOFE!$J:$J,'Part IX - Expenses'!$A28,SOFE!G:G) -> 9755 | G28: =+SUMIF(SOFE!K:K,'Part IX - Expenses'!A28,SOFE!I:I) -> 11590.21
A29: 20 | B29: Interest | C29: =SUM(D29:F29) -> 16850 | D29: =+SUMIF(SOFE!$J:$J,'Part IX - Expenses'!$A29,SOFE!E:E) -> 15014 | E29: =+SUMIF(SOFE!$J:$J,'Part IX - Expenses'!$A29,SOFE!F:F) -> 1391 | F29: =+SUMIF(SOFE!$J:$J,'Part IX - Expenses'!$A29,SOFE!G:G) -> 445 | G29: =+SUMIF(SOFE!K:K,'Part IX - Expenses'!A29,SOFE!I:I) -> 2345
A30: 21 | B30: Payments to affiliates | C30: =SUM(D30:F30) -> 0 | D30: =+SUMIF(SOFE!$J:$J,'Part IX - Expenses'!$A30,SOFE!E:E) -> 0 | E30: =+SUMIF(SOFE!$J:$J,'Part IX - Expenses'!$A30,SOFE!F:F) -> 0 | F30: =+SUMIF(SOFE!$J:$J,'Part IX - Expenses'!$A30,SOFE!G:G) -> 0 | G30: =+SUMIF(SOFE!K:K,'Part IX - Expenses'!A30,SOFE!I:I) -> 0
A31: 22 | B31: Depreciation, depletion and amortization | C31: =SUM(D31:F31) -> 183313 | D31: =+SUMIF(SOFE!$J:$J,'Part IX - Expenses'!$A31,SOFE!E:E) -> 160413 | E31: =+SUMIF(SOFE!$J:$J,'Part IX - Expenses'!$A31,SOFE!F:F) -> 18147 | F31: =+SUMIF(SOFE!$J:$J,'Part IX - Expenses'!$A31,SOFE!G:G) -> 4753 | G31: =+SUMIF(SOFE!K:K,'Part IX - Expenses'!A31,SOFE!I:I) -> 29684
A32: 23 | B32: Insurance | C32: =SUM(D32:F32) -> 9450 | D32: =+SUMIF(SOFE!$J:$J,'Part IX - Expenses'!$A32,SOFE!E:E) -> 7992 | E32: =+SUMIF(SOFE!$J:$J,'Part IX - Expenses'!$A32,SOFE!F:F) -> 882 | F32: =+SUMIF(SOFE!$J:$J,'Part IX - Expenses'!$A32,SOFE!G:G) -> 576 | G32: =+SUMIF(SOFE!K:K,'Part IX - Expenses'!A32,SOFE!I:I) -> 8374
A33: 24 | B33: Other Expenses. Itemize expenses not covered above (List Misc. expenses on 24e and not on lines 24a-d. If line 24e amount exceeds 10% of line 25, column(A) amouont, list line 24e expenses on schedule O) | G33: =+SUMIF(SOFE!K:K,'Part IX - Expenses'!A33,SOFE!I:I) -> 0
A34: 24a | B34: =IFERROR(INDEX(SOFE!$A:$J,MATCH('Part IX - Expenses'!A34,SOFE!$J:$J,0),1),"") -> Other Grants | C34: =SUM(D34:F34) -> 1586 | D34: =+SUMIF(SOFE!$J:$J,'Part IX - Expenses'!$A34,SOFE!E:E) -> 0 | E34: =+SUMIF(SOFE!$J:$J,'Part IX - Expenses'!$A34,SOFE!F:F) -> 1586 | F34: =+SUMIF(SOFE!$J:$J,'Part IX - Expenses'!$A34,SOFE!G:G) -> 0 | G34: =+SUMIF(SOFE!K:K,'Part IX - Expenses'!A34,SOFE!I:I) -> 66193
A35: 24b | B35: =IFERROR(INDEX(SOFE!$A:$J,MATCH('Part IX - Expenses'!A35,SOFE!$J:$J,0),1),"") | C35: =SUM(D35:F35) -> 0 | D35: =+SUMIF(SOFE!$J:$J,'Part IX - Expenses'!$A35,SOFE!E:E) -> 0 | E35: =+SUMIF(SOFE!$J:$J,'Part IX - Expenses'!$A35,SOFE!F:F) -> 0 | F35: =+SUMIF(SOFE!$J:$J,'Part IX - Expenses'!$A35,SOFE!G:G) -> 0 | G35: =+SUMIF(SOFE!K:K,'Part IX - Expenses'!A35,SOFE!I:I) -> 0
A36: 24c | B36: =IFERROR(INDEX(SOFE!$A:$J,MATCH('Part IX - Expenses'!A36,SOFE!$J:$J,0),1),"") | C36: =SUM(D36:F36) -> 0 | D36: =+SUMIF(SOFE!$J:$J,'Part IX - Expenses'!$A36,SOFE!E:E) -> 0 | E36: =+SUMIF(SOFE!$J:$J,'Part IX - Expenses'!$A36,SOFE!F:F) -> 0 | F36: =+SUMIF(SOFE!$J:$J,'Part IX - Expenses'!$A36,SOFE!G:G) -> 0 | G36: =+SUMIF(SOFE!K:K,'Part IX - Expenses'!A36,SOFE!I:I) -> 0
A37: 24d | B37: =IFERROR(INDEX(SOFE!$A:$J,MATCH('Part IX - Expenses'!A37,SOFE!$J:$J,0),1),"") | C37: =SUM(D37:F37) -> 0 | D37: =+SUMIF(SOFE!$J:$J,'Part IX - Expenses'!$A37,SOFE!E:E) -> 0 | E37: =+SUMIF(SOFE!$J:$J,'Part IX - Expenses'!$A37,SOFE!F:F) -> 0 | F37: =+SUMIF(SOFE!$J:$J,'Part IX - Expenses'!$A37,SOFE!G:G) -> 0 | G37: =+SUMIF(SOFE!K:K,'Part IX - Expenses'!A37,SOFE!I:I) -> 0
A38: 24e | B38: All Other | C38: =SUM(D38:F38) -> 0 | D38: =+SUMIF(SOFE!$J:$J,'Part IX - Expenses'!$A38,SOFE!E:E) -> 0 | E38: =+SUMIF(SOFE!$J:$J,'Part IX - Expenses'!$A38,SOFE!F:F) -> 0 | F38: =+SUMIF(SOFE!$J:$J,'Part IX - Expenses'!$A38,SOFE!G:G) -> 0 | G38: =+SUMIF(SOFE!K:K,'Part IX - Expenses'!A38,SOFE!I:I) -> 0
A39: 25 | B39: Total Functional Expenses | C39: =SUM(C4:C38) -> 12083062 | D39: =SUM(D4:D38) -> 10797432 | E39: =SUM(E4:E38) -> 986921.29 | F39: =SUM(F4:F38) -> 298709.25 | G39: =SUM(G4:G38) -> 6154687.5

Sheet Part X - Balance Sheet
A2: Part X - Balance Sheet
B3: Line | C3: Particulars | D3: Beginning of year | E3: End of Year
A4: Assets | B4: 1 | C4: Cash - Non Interest Bearing | D4: =+SUMIF(SOFP!$E:$E,'Part X - Balance Sheet'!B4,SOFP!$C:$C) -> 809592.71 | E4: =+SUMIF(SOFP!$F:$F,'Part X - Balance Sheet'!B4,SOFP!$D:$D) -> 1118499
B5: 2 | C5: Saving and Temporary Cash Investments | D5: =+SUMIF(SOFP!$E:$E,'Part X - Balance Sheet'!B5,SOFP!$C:$C) -> 2070590.3 | E5: =+SUMIF(SOFP!$F:$F,'Part X - Balance Sheet'!B5,SOFP!$D:$D) -> 0
B6: 3 | C6: Pledges and grants receivable, net | D6: =+SUMIF(SOFP!$E:$E,'Part X - Balance Sheet'!B6,SOFP!$C:$C) -> 1000625 | E6: =+SUMIF(SOFP!$F:$F,'Part X - Balance Sheet'!B6,SOFP!$D:$D) -> 2599240
B7: 4 | C7: Accounts Receivable, net | D7: =+SUMIF(SOFP!$E:$E,'Part X - Balance Sheet'!B7,SOFP!$C:$C) -> 3706 | E7: =+SUMIF(SOFP!$F:$F,'Part X - Balance Sheet'!B7,SOFP!$D:$D) -> 0
B8: 5 | C8: Receivables from Current and Former Officers, Directors, Trustees, Key Employees, creator or founder, substantial contributor, or 35% controlled entity or family member of any of these persons (Sch. L) | D8: =+SUMIF(SOFP!$E:$E,'Part X - Balance Sheet'!B8,SOFP!$C:$C) -> 0 | E8: =+SUMIF(SOFP!$F:$F,'Part X - Balance Sheet'!B8,SOFP!$D:$D) -> 0
B9: 6 | C9: Receivables from other Disqulified Persons | D9: =+SUMIF(SOFP!$E:$E,'Part X - Balance Sheet'!B9,SOFP!$C:$C) -> 0 | E9: =+SUMIF(SOFP!$F:$F,'Part X - Balance Sheet'!B9,SOFP!$D:$D) -> 0
B10: 7 | C10: Notes and Loans Receivable, net | D10: =+SUMIF(SOFP!$E:$E,'Part X - Balance Sheet'!B10,SOFP!$C:$C) -> 0 | E10: =+SUMIF(SOFP!$F:$F,'Part X - Balance Sheet'!B10,SOFP!$D:$D) -> 0
B11: 8 | C11: Inventories for sale or use | D11: =+SUMIF(SOFP!$E:$E,'Part X - Balance Sheet'!B11,SOFP!$C:$C) -> 3210 | E11: =+SUMIF(SOFP!$F:$F,'Part X - Balance Sheet'!B11,SOFP!$D:$D) -> 2361
B12: 9 | C12: Prepaid Expenses and Deferred Charges | D12: =+SUMIF(SOFP!$E:$E,'Part X - Balance Sheet'!B12,SOFP!$C:$C) -> 63626 | E12: =+SUMIF(SOFP!$F:$F,'Part X - Balance Sheet'!B12,SOFP!$D:$D) -> 45259
B13: 10a | C13: Land, Buildings and Equipment | D13: =+SUMIF(SOFP!$E:$E,'Part X - Balance Sheet'!B13,SOFP!$C:$C) -> 40391 | E13: =+SUMIF(SOFP!$F:$F,'Part X - Balance Sheet'!B13,SOFP!$D:$D) -> 40391
B14: 10b | C14: Less: Accumulated Depriciation | D14: =+SUMIF(SOFP!$E:$E,'Part X - Balance Sheet'!B14,SOFP!$C:$C) -> 30667 | E14: =+SUMIF(SOFP!$F:$F,'Part X - Balance Sheet'!B14,SOFP!$D:$D) -> 33952
C15: Land, Buildings and Equipment - Net | D15: =+D13-D14 -> 9724 | E15: =+E13-E14 -> 6439
B16: 11 | C16: Investments - Publicly Traded Securities | D16: =+SUMIF(SOFP!$E:$E,'Part X - Balance Sheet'!B16,SOFP!$C:$C) -> 0 | E16: =+SUMIF(SOFP!$F:$F,'Part X - Balance Sheet'!B16,SOFP!$D:$D) -> 0
B17: 12 | C17: Investments - OtherSecurities | D17: =+SUMIF(SOFP!$E:$E,'Part X - Balance Sheet'!B17,SOFP!$C:$C) -> 412460 | E17: =+SUMIF(SOFP!$F:$F,'Part X - Balance Sheet'!B17,SOFP!$D:$D) -> 975077
B18: 13 | C18: Investments - Program related | D18: =+SUMIF(SOFP!$E:$E,'Part X - Balance Sheet'!B18,SOFP!$C:$C) -> 0 | E18: =+SUMIF(SOFP!$F:$F,'Part X - Balance Sheet'!B18,SOFP!$D:$D) -> 0
B19: 14 | C19: Intangible Assets | D19: =+SUMIF(SOFP!$E:$E,'Part X - Balance Sheet'!B19,SOFP!$C:$C) -> 342890 | E19: =+SUMIF(SOFP!$F:$F,'Part X - Balance Sheet'!B19,SOFP!$D:$D) -> 556564
B20: 15 | C20: Other assets | D20: =+SUMIF(SOFP!$E:$E,'Part X - Balance Sheet'!B20,SOFP!$C:$C) -> 29175 | E20: =+SUMIF(SOFP!$F:$F,'Part X - Balance Sheet'!B20,SOFP!$D:$D) -> 29175
B21: 16 | C21: Total Assets | D21: =SUM(D4:D12,D15:D20) -> 4745599 | E21: =SUM(E4:E12,E15:E20) -> 5332614
A22: Liabilities | B22: 17 | C22: Accounts Payable and Accrued Expenses | D22: =+SUMIF(SOFP!$E:$E,'Part X - Balance Sheet'!B22,SOFP!$C:$C) -> 361056 | E22: =+SUMIF(SOFP!$F:$F,'Part X - Balance Sheet'!B22,SOFP!$D:$D) -> 1278580
B23: 18 | C23: Grants Payable | D23: =+SUMIF(SOFP!$E:$E,'Part X - Balance Sheet'!B23,SOFP!$C:$C) -> 0 | E23: =+SUMIF(SOFP!$F:$F,'Part X - Balance Sheet'!B23,SOFP!$D:$D) -> 0
B24: 19 | C24: Deferred Revenue | D24: =+SUMIF(SOFP!$E:$E,'Part X - Balance Sheet'!B24,SOFP!$C:$C) -> 0 | E24: =+SUMIF(SOFP!$F:$F,'Part X - Balance Sheet'!B24,SOFP!$D:$D) -> 1054229
B25: 20 | C25: Tax-Exempt Bond Liabilities | D25: =+SUMIF(SOFP!$E:$E,'Part X - Balance Sheet'!B25,SOFP!$C:$C) -> 0 | E25: =+SUMIF(SOFP!$F:$F,'Part X - Balance Sheet'!B25,SOFP!$D:$D) -> 0
B26: 21 | C26: Escrow or custodial account liability | D26: =+SUMIF(SOFP!$E:$E,'Part X - Balance Sheet'!B26,SOFP!$C:$C) -> 0 | E26: =+SUMIF(SOFP!$F:$F,'Part X - Balance Sheet'!B26,SOFP!$D:$D) -> 0
B27: 22 | C27: Payables to current or former Officers, Directors, Trustees and Key Employees, Highest compensated employees and disqualified persons | D27: =+SUMIF(SOFP!$E:$E,'Part X - Balance Sheet'!B27,SOFP!$C:$C) -> 0 | E27: =+SUMIF(SOFP!$F:$F,'Part X - Balance Sheet'!B27,SOFP!$D:$D) -> 0
B28: 23 | C28: Secured Mortgages and Notes Payable to unrelated third parties | D28: =+SUMIF(SOFP!$E:$E,'Part X - Balance Sheet'!B28,SOFP!$C:$C) -> 0 | E28: =+SUMIF(SOFP!$F:$F,'Part X - Balance Sheet'!B28,SOFP!$D:$D) -> 0
B29: 24 | C29: Unsecured notes and loans payable to unrelated third parties | D29: =+SUMIF(SOFP!$E:$E,'Part X - Balance Sheet'!B29,SOFP!$C:$C) -> 0 | E29: =+SUMIF(SOFP!$F:$F,'Part X - Balance Sheet'!B29,SOFP!$D:$D) -> 0
B30: 25 | C30: Other Liabilities (incl. federal income tax, payables to related thord parties and other liabilities not included above) | D30: =+SUMIF(SOFP!$E:$E,'Part X - Balance Sheet'!B30,SOFP!$C:$C) -> 342890 | E30: =+SUMIF(SOFP!$F:$F,'Part X - Balance Sheet'!B30,SOFP!$D:$D) -> 559692
B31: 26 | C31: Total Liabilities | D31: =+SUM(D22:D30) -> 703946 | E31: =+SUM(E22:E30) -> 2892501
A32: Net Assets or fund balances | C32: Organizations that follow FASB ASC 958, complete lines 27, 28, 32, and 33
B33: 27 | C33: Net assets without donor restrictions | D33: =+SUMIF(SOFP!$E:$E,'Part X - Balance Sheet'!B33,SOFP!$C:$C) -> 460416 | E33: =+SUMIF(SOFP!$F:$F,'Part X - Balance Sheet'!B33,SOFP!$D:$D) -> 103743
B34: 28 | C34: Net assets with donor restrictions | D34: =+SUMIF(SOFP!$E:$E,'Part X - Balance Sheet'!B34,SOFP!$C:$C) -> 3581237 | E34: =+SUMIF(SOFP!$F:$F,'Part X - Balance Sheet'!B34,SOFP!$D:$D) -> 2336370
C35: Organizations that do not follow FASB ASC 958, complete lines 29 through 33.
B36: 29 | C36: Capital Stock or trust principal or current funds | D36: =+SUMIF(SOFP!$E:$E,'Part X - Balance Sheet'!B36,SOFP!$C:$C) -> 0 | E36: =+SUMIF(SOFP!$F:$F,'Part X - Balance Sheet'!B36,SOFP!$D:$D) -> 0
B37: 30 | C37: Paid in or Capital Surplus, or land, building, or equipment funds | D37: =+SUMIF(SOFP!$E:$E,'Part X - Balance Sheet'!B37,SOFP!$C:$C) -> 0 | E37: =+SUMIF(SOFP!$F:$F,'Part X - Balance Sheet'!B37,SOFP!$D:$D) -> 0
B38: 31 | C38: Retained Earnings, endowment, accumulated income, or other funds | D38: =+SUMIF(SOFP!$E:$E,'Part X - Balance Sheet'!B38,SOFP!$C:$C) -> 0 | E38: =+SUMIF(SOFP!$F:$F,'Part X - Balance Sheet'!B38,SOFP!$D:$D) -> 0
B39: 32 | C39: Total Net Assets or Fund Balances | D39: =SUM(D33:D38) -> 4041653 | E39: =SUM(E33:E38) -> 2440113
B40: 33 | C40: Total Liabilities and Net Assets or Fund Balances | D40: =D31+D39 -> 4745599 | E40: =E31+E39 -> 5332614
D42: =+D21-D40 -> 0 | E42: =+E21-E40 -> 0 | F42: Check

Sheet Part XI - Net Asset Recon.
A2: Schedule D, Part XI - Recon. Of Revenue per AFS with Form 990
A3: Particulars | B3: Amount
A4: Total Revenue per AFS | B4: =+B14+B10-B13 -> 10524140
A6: a. New Unrealized Gains (losses) on Investments | B6: =+SUMIF(SOR!F:F,'Part XI - Net Asset Recon.'!C6,SOR!B:B) -> 30922 | C6: Adj-UG
A7: b. Donated Services and use of facilities | B7: =+SUMIF(SOR!F:F,'Part XI - Net Asset Recon.'!C7,SOR!B:B) -> 34712 | C7: Adj-DS
A8: c. Recoveries of Prior year Grants | B8: =+SUMIF(SOR!F:F,'Part XI - Net Asset Recon.'!C8,SOR!B:B) -> 0 | C8: Adj-PY
A9: d. Other | B9: =+SUMIF(SOR!F:F,'Part XI - Net Asset Recon.'!C9,SOR!B:B) -> 0 | C9: Adj-Other
B10: =+SUM(B6:B9) -> 65634
A11: a. Investment Expenses not included on Form 990, Part VIII, line 7b | B11: =+SUMIF(SOR!F:F,'Part XI - Net Asset Recon.'!C11,SOR!B:B) -> 0 | C11: Adj-IE
A12: b. Other | B12: 0
B13: =+SUM(B11:B12) -> 0
A14: Total Revenue (Part VIII , Line 12) | B14: =+'Part VIII - Revenue'!E48 -> 10458506
A17: Schedule D, Part XII - Recon. Of Expenses per AFS with Form 990
A18: Particulars | B18: Amount
A19: Total Expenses as per AFS | B19: =+B29+B25-B28 -> 12125680
A21: a. Donated Services and use of facilities | B21: =+SUMIF(SOFE!J:J,'Part XI - Net Asset Recon.'!C21,SOFE!H:H) -> 34712 | C21: Adj-DS
A22: b. PY Adjustments | B22: =+SUMIF(SOFE!J:J,'Part XI - Net Asset Recon.'!C22,SOFE!H:H) -> 0 | C22: Adj-PY
A23: c. Other Losses | B23: =+SUMIF(SOFE!J:J,'Part XI - Net Asset Recon.'!C23,SOFE!H:H) -> 0 | C23: Adj-Other Loss
A24: d. Other | B24: =+SUMIF(SOFE!J:J,'Part XI - Net Asset Recon.'!C24,SOFE!H:H) -> 7906 | C24: Adj-Other
B25: =+SUM(B21:B24) -> 42618
A26: a. Investment Expenses not included on Form 990, Part VIII, line 7b | B26: =+SUMIF(SOFE!J:J,'Part XI - Net Asset Recon.'!C26,SOFE!H:H) -> 0 | C26: Adj-IE
A27: b. Other | B27: 0
B28: =+SUM(B26:B27) -> 0
A29: Total Expenses (Part IX , Line 25) | B29: =+'Part IX - Expenses'!C39 -> 12083062
A33: Part XI - Reconciliation of Net Assets
A34: Particulars | B34: Amount
A35: 1. Total Revenue (must equal Part VIII, Column (A), line 12) | B35: =+'Part VIII - Revenue'!E48 -> 10458506
A36: 2. Total expenses (must equal Part IX, column (A), line 25) | B36: =+'Part IX - Expenses'!C39 -> 12083062
A37: 3. Revenue less expenses. Subtract line 2 from line 1 | B37: =B35-B36 -> -1624556.4
A38: 4. Net assets or fund balances at beginning of year (must equal Part X, line 32, column (A)) | B38: =+'Part X - Balance Sheet'!D39 -> 4041653
A39: 5. Net unrealized gains (losses) on investments | B39: =+B6 -> 30922 | C39: Adj-UG
A40: 6. Donated services and use of facilities | B40: =+IF(B7=B21,B7-B21,B7) -> 0 | C40: Adj-DS
A41: 7. Investment expenses | B41: 0 | C41: Adj-IE
A42: 8. Prior period adjustments | B42: =+IF(B8=B22,B8-B22,B8) -> 0 | C42: Adj-PY
A43: 9. Other changes in net assets or fund balances | B43: =-+IF(B9=B24,B9,SUM(B9+B24)) -> -7906
A44: 10. Net assets or fund balances at end of year. Combine lines 3 through 9 (must equal Part X, line 32, column (B)) | B44: =+SUM(B37:B43) -> 2440112.6
A46: Check | B46: =+B44-'Part X - Balance Sheet'!E39 -> -0.41

Sheet Queries

Sheet TB Mapping 
A3: Account | B3: Prelim | C3: Adj's | D3: Reclass | E3: Rep | F3: Annotation | G3: Rep 06/23 | H3: %Chg
A5: 1001 First Republic Bank | B5: 0 | C5: 0 | D5: 0 | E5: 0 | G5: 235234.64 | H5: -100
A6: 1002 FRB - ICS | B6: 0 | C6: 0 | D6: 0 | E6: 0 | G6: 1990834.7 | H6: -100
A7: 1003 Chase Bank | B7: 1104428 | C7: 0 | D7: 0 | E7: 1104428 | G7: 0 | H7: 0
A8: 1010 Bank of America | B8: 0 | C8: 0 | D8: 0 | E8: 0 | G8: 516436.08 | H8: -100
A9: 1020 BOA - Money Market | B9: 0 | C9: 0 | D9: 0 | E9: 0 | G9: 79755.62 | H9: -100
A10: 1070 Petty Cash | B10: 101 | C10: 0 | D10: 0 | E10: 101 | G10: 120.27 | H10: -16
A11: 1072 Petty Cash for Refugees | B11: 3375 | C11: 0 | D11: 0 | E11: 3375 | G11: 3800 | H11: -11
A12: 1080 PayPal | B12: 10595 | C12: 0 | D12: 0 | E12: 10595 | G12: 54001.73 | H12: -80
A13: 10000 Cash and Cash Equivalents | B13: 1118499 | C13: 0 | D13: 0 | E13: 1118499 | G13: 2880183 | H13: -61
A15: 1305 Investments:RBC | B15: 277185 | C15: 0 | D15: 0 | E15: 277185 | G15: 258295.07 | H15: 7
A16: 1306 Investments:JSV Investment | B16: 172808 | C16: 0 | D16: 0 | E16: 172808 | G16: 154165 | H16: 12
A17: 1308 RBC- Endowment | B17: 525084 | C17: 0 | D17: 0 | E17: 525084 | G17: 0 | H17: 0 | J17: =+E17-525261 -> -177
A18: 11000 Investment | B18: 975077 | C18: 0 | D18: 0 | E18: 975077 | G18: 412460.07 | H18: 136
A20: 1200 Accounts Receivable | B20: 615104 | C20: 0 | D20: 0 | E20: 615104 | G20: 869889.38 | H20: -29
A21: 12100 Accounts Receivable | B21: 615104 | C21: 0 | D21: 0 | E21: 615104 | G21: 869889.38 | H21: -29
A23: 1235 Grant Rev Not Billed | B23: 1726113 | C23: 0 | D23: 0 | E23: 1726113 | G23: 0 | H23: 0
A24: 12200 Grants Receivable | B24: 1726113 | C24: 0 | D24: 0 | E24: 1726113 | G24: 0 | H24: 0
A26: 1210 Allowance on Pledges Receivable | B26: -5249 | C26: -7906 | D26: 0 | E26: -13155 | G26: -5249 | H26: 151
A27: 1215 Pledges Receivable | B27: 271178 | C27: 0 | D27: 0 | E27: 271178 | G27: 135985.42 | H27: 99
A28: 12500 Pledges Receivable | B28: 265929 | C28: -7906 | D28: 0 | E28: 258023 | G28: 130736.42 | H28: 97
A30: 1301 Benefits Receivable | B30: 0 | C30: 0 | D30: 0 | E30: 0 | G30: 3705.87 | H30: -100
A31: 12700 Benefits Receivable | B31: 0 | C31: 0 | D31: 0 | E31: 0 | G31: 3705.87 | H31: -100
A33: 1303 Deposits | B33: 29175 | C33: 0 | D33: 0 | E33: 29175 | G33: 29174.76 | H33: 0
A34: 12800 Deposit | B34: 29175 | C34: 0 | D34: 0 | E34: 29175 | G34: 29174.76 | H34: 0
... A203: 57000 Bad Debts Expenses | B203: 0 | C203: 7906 | D203: 0 | E203: 7906 | G203: 23777.21 | H203: -67
B205: 1590507 | C205: 11034 | D205: 0 | E205: 1601541 | G205: -2275351.3 | H205: -170
A207: 45747
A208: 10:15 PM

Sheet Function Exp
I1: 1060 - Security Program | K1: 1000 - Admin - Other | M1: m | O1: 3100 - L'Dor V'Dor Society | Q1: 2020 - Moca Foundation | S1: 2000 - Fundraising - Other | U1: F | W1: 4102 - CA ACS | Y1: 4103 - CA AIRS | AA1: 4201 - GG | AC1: 4203 - Match | AE1: 4202 - WF | AG1: Total 4200 - Claims Conference | AI1: 4301 - Afghan | AK1: 4303 - County - Other | AM1: 4302 - Ukraine | AO1: 4300 - County of Santa Clara - Other | AQ1: Total 4300 - County of Santa Clara | AS1: 4400 - Health Navigator (RHPP) | AU1: 4501 - ERMA | AW1: 4505 - PC | AY1: 4506 - PC REA | BA1: 4507 - PC Sup | BC1: 4508 - PC Ukraine | BE1: 4503 - R&P | BG1: 4504 - R&P Addtl | BI1: R&P Afghan Refugees & SIV | BK1: 4500 - HIAS - Other | BM1: Total 4500 - HIAS | BO1: Total 4100 - Contract | BQ1: 7010 - Center for Aging - Rest | BS1: City of Fremont | BU1: 7030 - ECH | BW1: 7040 - EFRS | BY1: 7105 - EFSP | CA1: 7060 - Holocaust | CC1: 7070 - KAVOD | CE1: 7103 - Equipped To Learn | CG1: 7101 - Berkowitz Food Fund | CI1: 7102 - EAF | CK1: 7104 - General | CM1: Total 7100 - NOAH | CO1: Older Adult Mental Health | CQ1: 7300 - Ref Resettle & Housing | CS1: Total 7000 - Restricted | CU1: p
I2: (1000 - Admin) | K2: (1000 - Admin) | M2: Total 1000 - Admin | O2: (2000 - Fundraising) | Q2: (2000 - Fundraising) | S2: (2000 - Fundraising) | U2: Total 2000 - Fundraising | W2: (4100 - Contract) | Y2: (4100 - Contract) | AA2: (4200 - Claims Conference) | AC2: (4200 - Claims Conference) | AE2: (4200 - Claims Conference) | AG2: (4100 - Contract) | AI2: (4300 - County of Santa Clara) | AK2: (4300 - County of Santa Clara) | AM2: (4300 - County of Santa Clara) | AO2: (4300 - County of Santa Clara) | AQ2: (4100 - Contract) | AS2: (4100 - Contract) | AU2: (4500 - HIAS) | AW2: (4500 - HIAS) | AY2: (4500 - HIAS) | BA2: (4500 - HIAS) | BC2: (4500 - HIAS) | BE2: (4500 - HIAS) | BG2: (4500 - HIAS) | BI2: (4500 - HIAS) | BK2: (4500 - HIAS) | BM2: (4100 - Contract) | BO2: (4000 - Program) | BQ2: (7000 - Restricted) | BS2: (7000 - Restricted) | BU2: (7000 - Restricted) | BW2: (7000 - Restricted) | BY2: (7000 - Restricted) | CA2: (7000 - Restricted) | CC2: (7000 - Restricted) | CE2: (7100 - NOAH) | CG2: (7100 - NOAH) | CI2: (7100 - NOAH) | CK2: (7100 - NOAH) | CM2: (7000 - Restricted) | CO2: (7000 - Restricted) | CQ2: (7000 - Restricted) | CS2: (4000 - Program) | CU2: Total 4000 - Program | CW2: Unclassified | CY2: TOTAL | DA2: Aging | DC2: Refugee
B3: Ordinary Income/Expense
D4: Income
E5: 4000 · Contracts | I5: 0 | K5: 0 | M5: =ROUND(SUM(I5:K5),5) -> 0 | O5: 0 | Q5: 0 | S5: 0 | U5: =ROUND(SUM(O5:S5),5) -> 0 | W5: 185471.06 | Y5: 133162.81 | AA5: 4727288.3 | AC5: 14867 | AE5: 7358.96 | AG5: =ROUND(SUM(AA5:AE5),5) -> 4749514.3 | AI5: 266334.4 | AK5: 244176.82 | AM5: 335392.94 | AO5: 809780.49 | AQ5: =ROUND(SUM(AI5:AO5),5) -> 1655684.6 | AS5: 93881.38 | AU5: 122111.69 | AW5: 105105.92 | AY5: 84203.49 | BA5: 360224.52 | BC5: 96751.88 | BE5: 586987.54 | BG5: 6943.39 | BI5: 214063.67 | BK5: 0 | BM5: =ROUND(SUM(AU5:BK5),5) -> 1576392.1 | BO5: =ROUND(SUM(W5:Y5)+AG5+SUM(AQ5:AS5)+BM5,5) -> 8394106.3 | BQ5: 0 | BS5: 0 | BU5: 0 | BW5: 0 | BY5: 0 | CA5: 0 | CC5: 0 | CE5: 0 | CG5: 0 | CI5: 0 | CK5: 0 | CM5: =ROUND(SUM(CE5:CK5),5) -> 0 | CO5: 0 | CQ5: 0 | CS5: =ROUND(SUM(BQ5:CC5)+SUM(CM5:CQ5),5) -> 0 | CU5: =ROUND(BO5+CS5,5) -> 8394106.3 | CW5: 0 | CY5: =ROUND(M5+U5+SUM(CU5:CW5),5) -> 8394106.3
E6: 4300 · Donations & Fundraising | I6: 0 | K6: 13572.42 | M6: =ROUND(SUM(I6:K6),5) -> 13572.42 | O6: 520130.01 | Q6: 0 | S6: 364215.03 | U6: =ROUND(SUM(O6:S6),5) -> 884345.04 | W6: 0 | Y6: 0 | AA6: 0 | AC6: 0 | AE6: 0 | AG6: =ROUND(SUM(AA6:AE6),5) -> 0 | AI6: 0 | AK6: 0 | AM6: 0 | AO6: 0 | AQ6: =ROUND(SUM(AI6:AO6),5) -> 0 | AS6: 0 | AU6: 0 | AW6: 0 | AY6: 0 | BA6: 0 | BC6: 0 | BE6: 100 | BG6: 0 | BI6: 0 | BK6: 441.31 | BM6: =ROUND(SUM(AU6:BK6),5) -> 541.31 | BO6: =ROUND(SUM(W6:Y6)+AG6+SUM(AQ6:AS6)+BM6,5) -> 541.31 | BQ6: 0 | BS6: 0 | BU6: 0 | BW6: 6366.69 | BY6: 0 | CA6: 0 | CC6: 0 | CE6: 3463 | CG6: 25 | CI6: 0 | CK6: 0 | CM6: =ROUND(SUM(CE6:CK6),5) -> 3488 | CO6: 207.56 | CQ6: 0 | CS6: =ROUND(SUM(BQ6:CC6)+SUM(CM6:CQ6),5) -> 10062.25 | CU6: =ROUND(BO6+CS6,5) -> 10603.56 | CW6: 0 | CY6: =ROUND(M6+U6+SUM(CU6:CW6),5) -> 908521.02
E7: 4400 · Events | I7: 0 | K7: 0 | M7: =ROUND(SUM(I7:K7),5) -> 0 | O7: 0 | Q7: 0 | S7: 146974.67 | U7: =ROUND(SUM(O7:S7),5) -> 146974.67 | W7: 0 | Y7: 0 | AA7: 0 | AC7: 0 | AE7: 0 | AG7: =ROUND(SUM(AA7:AE7),5) -> 0 | AI7: 0 | AK7: 0 | AM7: 0 | AO7: 0 | AQ7: =ROUND(SUM(AI7:AO7),5) -> 0 | AS7: 0 | AU7: 0 | AW7: 0 | AY7: 0 | BA7: 0 | BC7: 0 | BE7: 0 | BG7: 0 | BI7: 0 | BK7: 0 | BM7: =ROUND(SUM(AU7:BK7),5) -> 0 | BO7: =ROUND(SUM(W7:Y7)+AG7+SUM(AQ7:AS7)+BM7,5) -> 0 | BQ7: 664.15 | BS7: 0 | BU7: 0 | BW7: 456.58 | BY7: 0 | CA7: 4209.13 | CC7: 0 | CE7: 0 | CG7: 373.37 | CI7: 0 | CK7: 0 | CM7: =ROUND(SUM(CE7:CK7),5) -> 373.37 | CO7: 0 | CQ7: 0 | CS7: =ROUND(SUM(BQ7:CC7)+SUM(CM7:CQ7),5) -> 5703.23 | CU7: =ROUND(BO7+CS7,5) -> 5703.23 | CW7: 0 | CY7: =ROUND(M7+U7+SUM(CU7:CW7),5) -> 152677.9
E8: Counseling and Homecare Fees | I8: 0 | K8: 0 | M8: =ROUND(SUM(I8:K8),5) -> 0 | O8: 0 | Q8: 0 | S8: 0 | U8: =ROUND(SUM(O8:S8),5) -> 0 | W8: 0 | Y8: 0 | AA8: 0 | AC8: 0 | AE8: 0 | AG8: =ROUND(SUM(AA8:AE8),5) -> 0 | AI8: 0 | AK8: 0 | AM8: 0 | AO8: 0 | AQ8: =ROUND(SUM(AI8:AO8),5) -> 0 | AS8: 0 | AU8: 0 | AW8: 0 | AY8: 0 | BA8: 0 | BC8: 0 | BE8: 0 | BG8: 0 | BI8: 0 | BK8: 0 | BM8: =ROUND(SUM(AU8:BK8),5) -> 0 | BO8: =ROUND(SUM(W8:Y8)+AG8+SUM(AQ8:AS8)+BM8,5) -> 0 | BQ8: 12179.1 | BS8: 0 | BU8: 0 | BW8: 0 | BY8: 0 | CA8: 0 | CC8: 0 | CE8: 0 | CG8: 0 | CI8: 0 | CK8: 0 | CM8: =ROUND(SUM(CE8:CK8),5) -> 0 | CO8: 0 | CQ8: 0 | CS8: =ROUND(SUM(BQ8:CC8)+SUM(CM8:CQ8),5) -> 12179.1 | CU8: =ROUND(BO8+CS8,5) -> 12179.1 | CW8: 0 | CY8: =ROUND(M8+U8+SUM(CU8:CW8),5) -> 12179.1
E9: 4110 · Grants | I9: 0 | K9: 0 | M9: =ROUND(SUM(I9:K9),5) -> 0 | O9: 0 | Q9: 0 | S9: 130000 | U9: =ROUND(SUM(O9:S9),5) -> 130000 | W9: 0 | Y9: 0 | AA9: 0 | AC9: 0 | AE9: 0 | AG9: =ROUND(SUM(AA9:AE9),5) -> 0 | AI9: 0 | AK9: 0 | AM9: 0 | AO9: 0 | AQ9: =ROUND(SUM(AI9:AO9),5) -> 0 | AS9: 0 | AU9: 0 | AW9: 0 | AY9: 0 | BA9: 0 | BC9: 0 | BE9: 0 | BG9: 0 | BI9: 0 | BK9: 0 | BM9: =ROUND(SUM(AU9:BK9),5) -> 0 | BO9: =ROUND(SUM(W9:Y9)+AG9+SUM(AQ9:AS9)+BM9,5) -> 0 | BQ9: 100075 | BS9: 0 | BU9: 0 | BW9: 0 | BY9: 0 | CA9: 0 | CC9: 0 | CE9: 0 | CG9: 25000 | CI9: 0 | CK9: 0 | CM9: =ROUND(SUM(CE9:CK9),5) -> 25000 | CO9: 0 | CQ9: 0 | CS9: =ROUND(SUM(BQ9:CC9)+SUM(CM9:CQ9),5) -> 125075 | CU9: =ROUND(BO9+CS9,5) -> 125075 | CW9: 0 | CY9: =ROUND(M9+U9+SUM(CU9:CW9),5) -> 255075
E10: 4600 · Investment Income | I10: 0 | K10: 176083.77 | M10: =ROUND(SUM(I10:K10),5) -> 176083.77 | O10: 0 | Q10: 0 | S10: 0 | U10: =ROUND(SUM(O10:S10),5) -> 0 | W10: 0 | Y10: 0 | AA10: 0 | AC10: 0 | AE10: 0 | AG10: =ROUND(SUM(AA10:AE10),5) -> 0 | AI10: 0 | AK10: 0 | AM10: 0 | AO10: 0 | AQ10: =ROUND(SUM(AI10:AO10),5) -> 0 | AS10: 0 | AU10: 0 | AW10: 0 | AY10: 0 | BA10: 0 | BC10: 0 | BE10: 0 | BG10: 0 | BI10: 0 | BK10: 0 | BM10: =ROUND(SUM(AU10:BK10),5) -> 0 | BO10: =ROUND(SUM(W10:Y10)+AG10+SUM(AQ10:AS10)+BM10,5) -> 0 | BQ10: 0 | BS10: 0 | BU10: 0 | BW10: 0 | BY10: 0 | CA10: 0 | CC10: 0 | CE10: 0 | CG10: 0 | CI10: 0 | CK10: 0 | CM10: =ROUND(SUM(CE10:CK10),5) -> 0 | CO10: 0 | CQ10: 0 | CS10: =ROUND(SUM(BQ10:CC10)+SUM(CM10:CQ10),5) -> 0 | CU10: =ROUND(BO10+CS10,5) -> 0 | CW10: 0 | CY10: =ROUND(M10+U10+SUM(CU10:CW10),5) -> 176083.77
E11: 4999 · Use of Restricted Funds | I11: 31653.96 | K11: 0 | M11: =ROUND(SUM(I11:K11),5) -> 31653.96 | O11: 0 | Q11: 9388.22 | S11: 0 | U11: =ROUND(SUM(O11:S11),5) -> 9388.22 | W11: 0 | Y11: 0 | AA11: 0 | AC11: 0 | AE11: 0 | AG11: =ROUND(SUM(AA11:AE11),5) -> 0 | AI11: 0 | AK11: 0 | AM11: 0 | AO11: 0 | AQ11: =ROUND(SUM(AI11:AO11),5) -> 0 | AS11: 0 | AU11: 0 | AW11: 0 | AY11: 0 | BA11: 0 | BC11: 0 | BE11: 0 | BG11: 0 | BI11: 0 | BK11: 0 | BM11: =ROUND(SUM(AU11:BK11),5) -> 0 | BO11: =ROUND(SUM(W11:Y11)+AG11+SUM(AQ11:AS11)+BM11,5) -> 0 | BQ11: 656437.95 | BS11: 14824.25 | BU11: 76016.41 | BW11: 309217.69 | BY11: 60591.6 | CA11: 939038.84 | CC11: 72000 | CE11: 8130.95 | CG11: 1509.31 | CI11: 25538.5 | CK11: 252438.47 | CM11: =ROUND(SUM(CE11:CK11),5) -> 287617.23 | CO11: 50207.56 | CQ11: 15781.43 | CS11: =ROUND(SUM(BQ11:CC11)+SUM(CM11:CQ11),5) -> 2481733 | CU11: =ROUND(BO11+CS11,5) -> 2481733 | CW11: 0 | CY11: =ROUND(M11+U11+SUM(CU11:CW11),5) -> 2522775.1
D12: Total Income | I12: =ROUND(SUM(I4:I11),5) -> 31653.96 | K12: =ROUND(SUM(K4:K11),5) -> 189656.19 | M12: =ROUND(SUM(I12:K12),5) -> 221310.15 | O12: =ROUND(SUM(O4:O11),5) -> 520130.01 | Q12: =ROUND(SUM(Q4:Q11),5) -> 9388.22 | S12: =ROUND(SUM(S4:S11),5) -> 641189.7 | U12: =ROUND(SUM(O12:S12),5) -> 1170707.9 | W12: =ROUND(SUM(W4:W11),5) -> 185471.06 | Y12: =ROUND(SUM(Y4:Y11),5) -> 133162.81 | AA12: =ROUND(SUM(AA4:AA11),5) -> 4727288.3 | AC12: =ROUND(SUM(AC4:AC11),5) -> 14867 | AE12: =ROUND(SUM(AE4:AE11),5) -> 7358.96 | AG12: =ROUND(SUM(AA12:AE12),5) -> 4749514.3 | AI12: =ROUND(SUM(AI4:AI11),5) -> 266334.4 | AK12: =ROUND(SUM(AK4:AK11),5) -> 244176.82 | AM12: =ROUND(SUM(AM4:AM11),5) -> 335392.94 | AO12: =ROUND(SUM(AO4:AO11),5) -> 809780.49 | AQ12: =ROUND(SUM(AI12:AO12),5) -> 1655684.6 | AS12: =ROUND(SUM(AS4:AS11),5) -> 93881.38 | AU12: =ROUND(SUM(AU4:AU11),5) -> 122111.69 | AW12: =ROUND(SUM(AW4:AW11),5) -> 105105.92 | AY12: =ROUND(SUM(AY4:AY11),5) -> 84203.49 | BA12: =ROUND(SUM(BA4:BA11),5) -> 360224.52 | BC12: =ROUND(SUM(BC4:BC11),5) -> 96751.88 | BE12: =ROUND(SUM(BE4:BE11),5) -> 587087.54 | BG12: =ROUND(SUM(BG4:BG11),5) -> 6943.39 | BI12: =ROUND(SUM(BI4:BI11),5) -> 214063.67 | BK12: =ROUND(SUM(BK4:BK11),5) -> 441.31 | BM12: =ROUND(SUM(AU12:BK12),5) -> 1576933.4 | BO12: =ROUND(SUM(W12:Y12)+AG12+SUM(AQ12:AS12)+BM12,5) -> 8394647.6 | BQ12: =ROUND(SUM(BQ4:BQ11),5) -> 769356.2 | BS12: =ROUND(SUM(BS4:BS11),5) -> 14824.25 | BU12: =ROUND(SUM(BU4:BU11),5) -> 76016.41 | BW12: =ROUND(SUM(BW4:BW11),5) -> 316040.96 | BY12: =ROUND(SUM(BY4:BY11),5) -> 60591.6 | CA12: =ROUND(SUM(CA4:CA11),5) -> 943247.97 | CC12: =ROUND(SUM(CC4:CC11),5) -> 72000 | CE12: =ROUND(SUM(CE4:CE11),5) -> 11593.95 | CG12: =ROUND(SUM(CG4:CG11),5) -> 26907.68 | CI12: =ROUND(SUM(CI4:CI11),5) -> 25538.5 | CK12: =ROUND(SUM(CK4:CK11),5) -> 252438.47 | CM12: =ROUND(SUM(CE12:CK12),5) -> 316478.6 | CO12: =ROUND(SUM(CO4:CO11),5) -> 50415.12 | CQ12: =ROUND(SUM(CQ4:CQ11),5) -> 15781.43 | CS12: =ROUND(SUM(BQ12:CC12)+SUM(CM12:CQ12),5) -> 2634752.5 | CU12: =ROUND(BO12+CS12,5) -> 11029400 | CW12: =ROUND(SUM(CW4:CW11),5) -> 0 | CY12: =ROUND(M12+U12+SUM(CU12:CW12),5) -> 12421418
C13: Gross Profit | I13: =I12 -> 31653.96 | K13: =K12 -> 189656.19 | M13: =ROUND(SUM(I13:K13),5) -> 221310.15 | O13: =O12 -> 520130.01 | Q13: =Q12 -> 9388.22 | S13: =S12 -> 641189.7 | U13: =ROUND(SUM(O13:S13),5) -> 1170707.9 | W13: =W12 -> 185471.06 | Y13: =Y12 -> 133162.81 | AA13: =AA12 -> 4727288.3 | AC13: =AC12 -> 14867 | AE13: =AE12 -> 7358.96 | AG13: =ROUND(SUM(AA13:AE13),5) -> 4749514.3 | AI13: =AI12 -> 266334.4 | AK13: =AK12 -> 244176.82 | AM13: =AM12 -> 335392.94 | AO13: =AO12 -> 809780.49 | AQ13: =ROUND(SUM(AI13:AO13),5) -> 1655684.6 | AS13: =AS12 -> 93881.38 | AU13: =AU12 -> 122111.69 | AW13: =AW12 -> 105105.92 | AY13: =AY12 -> 84203.49 | BA13: =BA12 -> 360224.52 | BC13: =BC12 -> 96751.88 | BE13: =BE12 -> 587087.54 | BG13: =BG12 -> 6943.39 | BI13: =BI12 -> 214063.67 | BK13: =BK12 -> 441.31 | BM13: =ROUND(SUM(AU13:BK13),5) -> 1576933.4 | BO13: =ROUND(SUM(W13:Y13)+AG13+SUM(AQ13:AS13)+BM13,5) -> 8394647.6 | BQ13: =BQ12 -> 769356.2 | BS13: =BS12 -> 14824.25 | BU13: =BU12 -> 76016.41 | BW13: =BW12 -> 316040.96 | BY13: =BY12 -> 60591.6 | CA13: =CA12 -> 943247.97 | CC13: =CC12 -> 72000 | CE13: =CE12 -> 11593.95 | CG13: =CG12 -> 26907.68 | CI13: =CI12 -> 25538.5 | CK13: =CK12 -> 252438.47 | CM13: =ROUND(SUM(CE13:CK13),5) -> 316478.6 | CO13: =CO12 -> 50415.12 | CQ13: =CQ12 -> 15781.43 | CS13: =ROUND(SUM(BQ13:CC13)+SUM(CM13:CQ13),5) -> 2634752.5 | CU13: =ROUND(BO13+CS13,5) -> 11029400 | CW13: =CW12 -> 0 | CY13: =ROUND(M13+U13+SUM(CU13:CW13),5) -> 12421418
D14: Expense
E15: 6400 · Development Expenses
F16: 6410 · In-kind donation Expense | I16: 0 | K16: 0 | M16: =ROUND(SUM(I16:K16),5) -> 0 | O16: 0 | Q16: 0 | S16: 21247.77 | U16: =ROUND(SUM(O16:S16),5) -> 21247.77 | W16: 0 | Y16: 0 | AA16: 0 | AC16: 0 | AE16: 0 | AG16: =ROUND(SUM(AA16:AE16),5) -> 0 | AI16: 0 | AK16: 0 | AM16: 0 | AO16: 0 | AQ16: =ROUND(SUM(AI16:AO16),5) -> 0 | AS16: 0 | AU16: 0 | AW16: 0 | AY16: 0 | BA16: 0 | BC16: 0 | BE16: 0 | BG16: 0 | BI16: 0 | BK16: 0 | BM16: =ROUND(SUM(AU16:BK16),5) -> 0 | BO16: =ROUND(SUM(W16:Y16)+AG16+SUM(AQ16:AS16)+BM16,5) -> 0 | BQ16: 0 | BS16: 0 | BU16: 0 | BW16: 0 | BY16: 0 | CA16: 0 | CC16: 0 | CE16: 0 | CG16: 0 | CI16: 0 | CK16: 0 | CM16: =ROUND(SUM(CE16:CK16),5) -> 0 | CO16: 0 | CQ16: 0 | CS16: =ROUND(SUM(BQ16:CC16)+SUM(CM16:CQ16),5) -> 0 | CU16: =ROUND(BO16+CS16,5) -> 0 | CW16: 0 | CY16: =ROUND(M16+U16+SUM(CU16:CW16),5) -> 21247.77 | CZ16: 13 | DA16: =+CO16+CC16+CA16+BU16+BQ16+AG16 -> 0 | DC16: =+CQ16+BY16+BW16+BS16+BM16+AS16+AQ16+Y16+W16 -> 0
E17: Total 6400 · Development Expenses | I17: =ROUND(SUM(I15:I16),5) -> 0 | K17: =ROUND(SUM(K15:K16),5) -> 0 | M17: =ROUND(SUM(I17:K17),5) -> 0 | O17: =ROUND(SUM(O15:O16),5) -> 0 | Q17: =ROUND(SUM(Q15:Q16),5) -> 0 | S17: =ROUND(SUM(S15:S16),5) -> 21247.77 | U17: =ROUND(SUM(O17:S17),5) -> 21247.77 | W17: =ROUND(SUM(W15:W16),5) -> 0 | Y17: =ROUND(SUM(Y15:Y16),5) -> 0 | AA17: =ROUND(SUM(AA15:AA16),5) -> 0 | AC17: =ROUND(SUM(AC15:AC16),5) -> 0 | AE17: =ROUND(SUM(AE15:AE16),5) -> 0 | AG17: =ROUND(SUM(AA17:AE17),5) -> 0 | AI17: =ROUND(SUM(AI15:AI16),5) -> 0 | AK17: =ROUND(SUM(AK15:AK16),5) -> 0 | AM17: =ROUND(SUM(AM15:AM16),5) -> 0 | AO17: =ROUND(SUM(AO15:AO16),5) -> 0 | AQ17: =ROUND(SUM(AI17:AO17),5) -> 0 | AS17: =ROUND(SUM(AS15:AS16),5) -> 0 | AU17: =ROUND(SUM(AU15:AU16),5) -> 0 | AW17: =ROUND(SUM(AW15:AW16),5) -> 0 | AY17: =ROUND(SUM(AY15:AY16),5) -> 0 | BA17: =ROUND(SUM(BA15:BA16),5) -> 0 | BC17: =ROUND(SUM(BC15:BC16),5) -> 0 | BE17: =ROUND(SUM(BE15:BE16),5) -> 0 | BG17: =ROUND(SUM(BG15:BG16),5) -> 0 | BI17: =ROUND(SUM(BI15:BI16),5) -> 0 | BK17: =ROUND(SUM(BK15:BK16),5) -> 0 | BM17: =ROUND(SUM(AU17:BK17),5) -> 0 | BO17: =ROUND(SUM(W17:Y17)+AG17+SUM(AQ17:AS17)+BM17,5) -> 0 | BQ17: =ROUND(SUM(BQ15:BQ16),5) -> 0 | BS17: =ROUND(SUM(BS15:BS16),5) -> 0 | BU17: =ROUND(SUM(BU15:BU16),5) -> 0 | BW17: =ROUND(SUM(BW15:BW16),5) -> 0 | BY17: =ROUND(SUM(BY15:BY16),5) -> 0 | CA17: =ROUND(SUM(CA15:CA16),5) -> 0 | CC17: =ROUND(SUM(CC15:CC16),5) -> 0 | CE17: =ROUND(SUM(CE15:CE16),5) -> 0 | CG17: =ROUND(SUM(CG15:CG16),5) -> 0 | CI17: =ROUND(SUM(CI15:CI16),5) -> 0 | CK17: =ROUND(SUM(CK15:CK16),5) -> 0 | CM17: =ROUND(SUM(CE17:CK17),5) -> 0 | CO17: =ROUND(SUM(CO15:CO16),5) -> 0 | CQ17: =ROUND(SUM(CQ15:CQ16),5) -> 0 | CS17: =ROUND(SUM(BQ17:CC17)+SUM(CM17:CQ17),5) -> 0 | CU17: =ROUND(BO17+CS17,5) -> 0 | CW17: =ROUND(SUM(CW15:CW16),5) -> 0 | CY17: =ROUND(M17+U17+SUM(CU17:CW17),5) -> 21247.77 | DA17: =+CO17+CC17+CA17+BU17+BQ17+AG17 -> 0 | DC17: =+CQ17+BY17+BW17+BS17+BM17+AS17+AQ17+Y17+W17 -> 0
E18: 6000 · Indirect Costs | DA18: =+CO18+CC18+CA18+BU18+BQ18+AG18 -> 0 | DC18: =+CQ18+BY18+BW18+BS18+BM18+AS18+AQ18+Y18+W18 -> 0
F19: 6600 · Operating Expenses | DA19: =+CO19+CC19+CA19+BU19+BQ19+AG19 -> 0 | DC19: =+CQ19+BY19+BW19+BS19+BM19+AS19+AQ19+Y19+W19 -> 0
G20: 6602 · Advertising | I20: 0 | K20: 1074.39 | M20: =ROUND(SUM(I20:K20),5) -> 1074.39 | O20: 0 | Q20: 0 | S20: 184.77 | U20: =ROUND(SUM(O20:S20),5) -> 184.77 | W20: 0 | Y20: 0 | AA20: 0 | AC20: 0 | AE20: 0 | AG20: =ROUND(SUM(AA20:AE20),5) -> 0 | AI20: 0 | AK20: 0 | AM20: 0 | AO20: 0 | AQ20: =ROUND(SUM(AI20:AO20),5) -> 0 | AS20: 0 | AU20: 0 | AW20: 0 | AY20: 0 | BA20: 0 | BC20: 0 | BE20: 0 | BG20: 0 | BI20: 0 | BK20: 0 | BM20: =ROUND(SUM(AU20:BK20),5) -> 0 | BO20: =ROUND(SUM(W20:Y20)+AG20+SUM(AQ20:AS20)+BM20,5) -> 0 | BQ20: 1650 | BS20: 0 | BU20: 0 | BW20: 0 | BY20: 0 | CA20: 0 | CC20: 0 | CE20: 0 | CG20: 0 | CI20: 0 | CK20: 0 | CM20: =ROUND(SUM(CE20:CK20),5) -> 0 | CO20: 0 | CQ20: 0 | CS20: =ROUND(SUM(BQ20:CC20)+SUM(CM20:CQ20),5) -> 1650 | CU20: =ROUND(BO20+CS20,5) -> 1650 | CW20: 0 | CY20: =ROUND(M20+U20+SUM(CU20:CW20),5) -> 2909.16 | CZ20: 6 | DA20: =+CO20+CC20+CA20+BU20+BQ20+AG20 -> 1650 | DC20: =+CQ20+BY20+BW20+BS20+BM20+AS20+AQ20+Y20+W20 -> 0
G21: 6604 · Bank and Credit Card Charge | I21: 0 | K21: 4307.19 | M21: =ROUND(SUM(I21:K21),5) -> 4307.19 | O21: 88.82 | Q21: 0 | S21: 3184.23 | U21: =ROUND(SUM(O21:S21),5) -> 3273.05 | W21: 0 | Y21: 0 | AA21: 0 | AC21: 0 | AE21: 0 | AG21: =ROUND(SUM(AA21:AE21),5) -> 0 | AI21: 0 | AK21: 0 | AM21: 0 | AO21: 0 | AQ21: =ROUND(SUM(AI21:AO21),5) -> 0 | AS21: 0 | AU21: 0 | AW21: 0 | AY21: 0 | BA21: 0 | BC21: 0 | BE21: 0 | BG21: 0 | BI21: 0 | BK21: 0 | BM21: =ROUND(SUM(AU21:BK21),5) -> 0 | BO21: =ROUND(SUM(W21:Y21)+AG21+SUM(AQ21:AS21)+BM21,5) -> 0 | BQ21: 22.08 | BS21: 0 | BU21: 0 | BW21: 117.91 | BY21: 0 | CA21: 121.6 | CC21: 0 | CE21: 0 | CG21: 15.18 | CI21: 0 | CK21: 0 | CM21: =ROUND(SUM(CE21:CK21),5) -> 15.18 | CO21: 6.09 | CQ21: 0 | CS21: =ROUND(SUM(BQ21:CC21)+SUM(CM21:CQ21),5) -> 282.86 | CU21: =ROUND(BO21+CS21,5) -> 282.86 | CW21: 0 | CY21: =ROUND(M21+U21+SUM(CU21:CW21),5) -> 7863.1 | CZ21: 7 | DA21: =+CO21+CC21+CA21+BU21+BQ21+AG21 -> 149.77 | DC21: =+CQ21+BY21+BW21+BS21+BM21+AS21+AQ21+Y21+W21 -> 117.91
G22: 6606 · Conference and Meetings | I22: 0 | K22: 12479.17 | M22: =ROUND(SUM(I22:K22),5) -> 12479.17 | O22: 0 | Q22: 9388.22 | S22: 366.57 | U22: =ROUND(SUM(O22:S22),5) -> 9754.79 | W22: 0 | Y22: 0 | AA22: 0 | AC22: 0 | AE22: 0 | AG22: =ROUND(SUM(AA22:AE22),5) -> 0 | AI22: 0 | AK22: 0 | AM22: 0 | AO22: 0 | AQ22: =ROUND(SUM(AI22:AO22),5) -> 0 | AS22: 0 | AU22: 0 | AW22: 0 | AY22: 0 | BA22: 0 | BC22: 0 | BE22: 0 | BG22: 0 | BI22: 0 | BK22: 2379 | BM22: =ROUND(SUM(AU22:BK22),5) -> 2379 | BO22: =ROUND(SUM(W22:Y22)+AG22+SUM(AQ22:AS22)+BM22,5) -> 2379 | BQ22: 5833.93 | BS22: 0 | BU22: 0 | BW22: 0 | BY22: 0 | CA22: 138.63 | CC22: 0 | CE22: 0 | CG22: 40.54 | CI22: 0 | CK22: 0 | CM22: =ROUND(SUM(CE22:CK22),5) -> 40.54 | CO22: 162 | CQ22: 0 | CS22: =ROUND(SUM(BQ22:CC22)+SUM(CM22:CQ22),5) -> 6175.1 | CU22: =ROUND(BO22+CS22,5) -> 8554.1 | CW22: 0 | CY22: =ROUND(M22+U22+SUM(CU22:CW22),5) -> 30788.06 | CZ22: 10 | DA22: =+CO22+CC22+CA22+BU22+BQ22+AG22 -> 6134.56 | DC22: =+CQ22+BY22+BW22+BS22+BM22+AS22+AQ22+Y22+W22 -> 2379
G23: 6630 · Office Expenses | DA23: =+CO23+CC23+CA23+BU23+BQ23+AG23 -> 0 | DC23: =+CQ23+BY23+BW23+BS23+BM23+AS23+AQ23+Y23+W23 -> 0
